2014-05-27 22:37:43,770 [ERROR] django.request: Internal Server Error: /articles/all
Traceback (most recent call last):
  File "/home/damon/Documents/Python/django-damon/local/lib/python2.7/site-packages/Django-1.6.4-py2.7.egg/django/core/handlers/base.py", line 90, in get_response
    response = middleware_method(request)
  File "/home/damon/Documents/Python/django-damon/local/lib/python2.7/site-packages/Django-1.6.4-py2.7.egg/django/middleware/common.py", line 71, in process_request
    if (not urlresolvers.is_valid_path(request.path_info, urlconf) and
  File "/home/damon/Documents/Python/django-damon/local/lib/python2.7/site-packages/Django-1.6.4-py2.7.egg/django/core/urlresolvers.py", line 596, in is_valid_path
    resolve(path, urlconf)
  File "/home/damon/Documents/Python/django-damon/local/lib/python2.7/site-packages/Django-1.6.4-py2.7.egg/django/core/urlresolvers.py", line 476, in resolve
    return get_resolver(urlconf).resolve(path)
  File "/home/damon/Documents/Python/django-damon/local/lib/python2.7/site-packages/Django-1.6.4-py2.7.egg/django/core/urlresolvers.py", line 337, in resolve
    for pattern in self.url_patterns:
  File "/home/damon/Documents/Python/django-damon/local/lib/python2.7/site-packages/Django-1.6.4-py2.7.egg/django/core/urlresolvers.py", line 365, in url_patterns
    patterns = getattr(self.urlconf_module, "urlpatterns", self.urlconf_module)
  File "/home/damon/Documents/Python/django-damon/local/lib/python2.7/site-packages/Django-1.6.4-py2.7.egg/django/core/urlresolvers.py", line 360, in urlconf_module
    self._urlconf_module = import_module(self.urlconf_name)
  File "/home/damon/Documents/Python/django-damon/local/lib/python2.7/site-packages/Django-1.6.4-py2.7.egg/django/utils/importlib.py", line 40, in import_module
    __import__(name)
  File "/home/damon/Documents/Python/django-damon/django_test/django_test/urls.py", line 2, in <module>
    from article.views import HelloTemplate
  File "/home/damon/Documents/Python/django-damon/django_test/article/views.py", line 7, in <module>
    from forms import ArticleForm
  File "/home/damon/Documents/Python/django-damon/django_test/article/forms.py", line 11, in <module>
    class CommentForm(forms.ModelForm):
  File "/home/damon/Documents/Python/django-damon/local/lib/python2.7/site-packages/Django-1.6.4-py2.7.egg/django/forms/models.py", line 292, in __new__
    raise FieldError(message)
FieldError: Unknown field(s) (name) specified for Comment
2014-05-27 22:37:44,421 [ERROR] django.request: Internal Server Error: /favicon.ico
Traceback (most recent call last):
  File "/home/damon/Documents/Python/django-damon/local/lib/python2.7/site-packages/Django-1.6.4-py2.7.egg/django/core/handlers/base.py", line 90, in get_response
    response = middleware_method(request)
  File "/home/damon/Documents/Python/django-damon/local/lib/python2.7/site-packages/Django-1.6.4-py2.7.egg/django/middleware/common.py", line 71, in process_request
    if (not urlresolvers.is_valid_path(request.path_info, urlconf) and
  File "/home/damon/Documents/Python/django-damon/local/lib/python2.7/site-packages/Django-1.6.4-py2.7.egg/django/core/urlresolvers.py", line 596, in is_valid_path
    resolve(path, urlconf)
  File "/home/damon/Documents/Python/django-damon/local/lib/python2.7/site-packages/Django-1.6.4-py2.7.egg/django/core/urlresolvers.py", line 476, in resolve
    return get_resolver(urlconf).resolve(path)
  File "/home/damon/Documents/Python/django-damon/local/lib/python2.7/site-packages/Django-1.6.4-py2.7.egg/django/core/urlresolvers.py", line 337, in resolve
    for pattern in self.url_patterns:
  File "/home/damon/Documents/Python/django-damon/local/lib/python2.7/site-packages/Django-1.6.4-py2.7.egg/django/core/urlresolvers.py", line 365, in url_patterns
    patterns = getattr(self.urlconf_module, "urlpatterns", self.urlconf_module)
  File "/home/damon/Documents/Python/django-damon/local/lib/python2.7/site-packages/Django-1.6.4-py2.7.egg/django/core/urlresolvers.py", line 360, in urlconf_module
    self._urlconf_module = import_module(self.urlconf_name)
  File "/home/damon/Documents/Python/django-damon/local/lib/python2.7/site-packages/Django-1.6.4-py2.7.egg/django/utils/importlib.py", line 40, in import_module
    __import__(name)
  File "/home/damon/Documents/Python/django-damon/django_test/django_test/urls.py", line 2, in <module>
    from article.views import HelloTemplate
  File "/home/damon/Documents/Python/django-damon/django_test/article/views.py", line 7, in <module>
    from forms import ArticleForm
  File "/home/damon/Documents/Python/django-damon/django_test/article/forms.py", line 11, in <module>
    class CommentForm(forms.ModelForm):
  File "/home/damon/Documents/Python/django-damon/local/lib/python2.7/site-packages/Django-1.6.4-py2.7.egg/django/forms/models.py", line 292, in __new__
    raise FieldError(message)
FieldError: Unknown field(s) (name) specified for Comment
2014-05-27 22:40:46,911 [WARNING] django.request: Not Found: /favicon.ico
2014-05-27 22:41:10,643 [ERROR] django.request: Internal Server Error: /articles/search/
Traceback (most recent call last):
  File "/home/damon/Documents/Python/django-damon/local/lib/python2.7/site-packages/Django-1.6.4-py2.7.egg/django/core/handlers/base.py", line 114, in get_response
    response = wrapped_callback(request, *callback_args, **callback_kwargs)
  File "/home/damon/Documents/Python/django-damon/django_test/article/views.py", line 26, in search_titles
    ix = open_dir(settings.WHOOSH_INDEX)
NameError: global name 'open_dir' is not defined
2014-05-27 22:41:12,346 [ERROR] django.request: Internal Server Error: /articles/search/
Traceback (most recent call last):
  File "/home/damon/Documents/Python/django-damon/local/lib/python2.7/site-packages/Django-1.6.4-py2.7.egg/django/core/handlers/base.py", line 114, in get_response
    response = wrapped_callback(request, *callback_args, **callback_kwargs)
  File "/home/damon/Documents/Python/django-damon/django_test/article/views.py", line 26, in search_titles
    ix = open_dir(settings.WHOOSH_INDEX)
NameError: global name 'open_dir' is not defined
2014-05-27 22:41:12,719 [ERROR] django.request: Internal Server Error: /articles/search/
Traceback (most recent call last):
  File "/home/damon/Documents/Python/django-damon/local/lib/python2.7/site-packages/Django-1.6.4-py2.7.egg/django/core/handlers/base.py", line 114, in get_response
    response = wrapped_callback(request, *callback_args, **callback_kwargs)
  File "/home/damon/Documents/Python/django-damon/django_test/article/views.py", line 26, in search_titles
    ix = open_dir(settings.WHOOSH_INDEX)
NameError: global name 'open_dir' is not defined
2014-05-27 22:41:16,450 [ERROR] django.request: Internal Server Error: /articles/search/
Traceback (most recent call last):
  File "/home/damon/Documents/Python/django-damon/local/lib/python2.7/site-packages/Django-1.6.4-py2.7.egg/django/core/handlers/base.py", line 114, in get_response
    response = wrapped_callback(request, *callback_args, **callback_kwargs)
  File "/home/damon/Documents/Python/django-damon/django_test/article/views.py", line 26, in search_titles
    ix = open_dir(settings.WHOOSH_INDEX)
NameError: global name 'open_dir' is not defined
2014-05-27 22:41:17,445 [ERROR] django.request: Internal Server Error: /articles/search/
Traceback (most recent call last):
  File "/home/damon/Documents/Python/django-damon/local/lib/python2.7/site-packages/Django-1.6.4-py2.7.egg/django/core/handlers/base.py", line 114, in get_response
    response = wrapped_callback(request, *callback_args, **callback_kwargs)
  File "/home/damon/Documents/Python/django-damon/django_test/article/views.py", line 26, in search_titles
    ix = open_dir(settings.WHOOSH_INDEX)
NameError: global name 'open_dir' is not defined
2014-05-27 22:41:18,728 [ERROR] django.request: Internal Server Error: /articles/search/
Traceback (most recent call last):
  File "/home/damon/Documents/Python/django-damon/local/lib/python2.7/site-packages/Django-1.6.4-py2.7.egg/django/core/handlers/base.py", line 114, in get_response
    response = wrapped_callback(request, *callback_args, **callback_kwargs)
  File "/home/damon/Documents/Python/django-damon/django_test/article/views.py", line 26, in search_titles
    ix = open_dir(settings.WHOOSH_INDEX)
NameError: global name 'open_dir' is not defined
2014-05-27 22:41:21,687 [ERROR] django.request: Internal Server Error: /articles/search/
Traceback (most recent call last):
  File "/home/damon/Documents/Python/django-damon/local/lib/python2.7/site-packages/Django-1.6.4-py2.7.egg/django/core/handlers/base.py", line 114, in get_response
    response = wrapped_callback(request, *callback_args, **callback_kwargs)
  File "/home/damon/Documents/Python/django-damon/django_test/article/views.py", line 26, in search_titles
    ix = open_dir(settings.WHOOSH_INDEX)
NameError: global name 'open_dir' is not defined
2014-05-27 22:41:44,170 [ERROR] django.request: Internal Server Error: /articles/search/
Traceback (most recent call last):
  File "/home/damon/Documents/Python/django-damon/local/lib/python2.7/site-packages/Django-1.6.4-py2.7.egg/django/core/handlers/base.py", line 114, in get_response
    response = wrapped_callback(request, *callback_args, **callback_kwargs)
  File "/home/damon/Documents/Python/django-damon/django_test/article/views.py", line 26, in search_titles
    ix = open_dir(settings.WHOOSH_INDEX)
NameError: global name 'open_dir' is not defined
2014-05-27 22:41:46,243 [ERROR] django.request: Internal Server Error: /articles/search/
Traceback (most recent call last):
  File "/home/damon/Documents/Python/django-damon/local/lib/python2.7/site-packages/Django-1.6.4-py2.7.egg/django/core/handlers/base.py", line 114, in get_response
    response = wrapped_callback(request, *callback_args, **callback_kwargs)
  File "/home/damon/Documents/Python/django-damon/django_test/article/views.py", line 26, in search_titles
    ix = open_dir(settings.WHOOSH_INDEX)
NameError: global name 'open_dir' is not defined
2014-05-27 22:41:47,592 [ERROR] django.request: Internal Server Error: /articles/search/
Traceback (most recent call last):
  File "/home/damon/Documents/Python/django-damon/local/lib/python2.7/site-packages/Django-1.6.4-py2.7.egg/django/core/handlers/base.py", line 114, in get_response
    response = wrapped_callback(request, *callback_args, **callback_kwargs)
  File "/home/damon/Documents/Python/django-damon/django_test/article/views.py", line 26, in search_titles
    ix = open_dir(settings.WHOOSH_INDEX)
NameError: global name 'open_dir' is not defined
2014-05-27 22:41:47,808 [ERROR] django.request: Internal Server Error: /articles/search/
Traceback (most recent call last):
  File "/home/damon/Documents/Python/django-damon/local/lib/python2.7/site-packages/Django-1.6.4-py2.7.egg/django/core/handlers/base.py", line 114, in get_response
    response = wrapped_callback(request, *callback_args, **callback_kwargs)
  File "/home/damon/Documents/Python/django-damon/django_test/article/views.py", line 26, in search_titles
    ix = open_dir(settings.WHOOSH_INDEX)
NameError: global name 'open_dir' is not defined
2014-05-27 22:41:49,494 [ERROR] django.request: Internal Server Error: /articles/search/
Traceback (most recent call last):
  File "/home/damon/Documents/Python/django-damon/local/lib/python2.7/site-packages/Django-1.6.4-py2.7.egg/django/core/handlers/base.py", line 114, in get_response
    response = wrapped_callback(request, *callback_args, **callback_kwargs)
  File "/home/damon/Documents/Python/django-damon/django_test/article/views.py", line 26, in search_titles
    ix = open_dir(settings.WHOOSH_INDEX)
NameError: global name 'open_dir' is not defined
2014-05-27 22:41:50,144 [ERROR] django.request: Internal Server Error: /articles/search/
Traceback (most recent call last):
  File "/home/damon/Documents/Python/django-damon/local/lib/python2.7/site-packages/Django-1.6.4-py2.7.egg/django/core/handlers/base.py", line 114, in get_response
    response = wrapped_callback(request, *callback_args, **callback_kwargs)
  File "/home/damon/Documents/Python/django-damon/django_test/article/views.py", line 26, in search_titles
    ix = open_dir(settings.WHOOSH_INDEX)
NameError: global name 'open_dir' is not defined
2014-05-27 22:41:50,158 [ERROR] django.request: Internal Server Error: /articles/search/
Traceback (most recent call last):
  File "/home/damon/Documents/Python/django-damon/local/lib/python2.7/site-packages/Django-1.6.4-py2.7.egg/django/core/handlers/base.py", line 114, in get_response
    response = wrapped_callback(request, *callback_args, **callback_kwargs)
  File "/home/damon/Documents/Python/django-damon/django_test/article/views.py", line 26, in search_titles
    ix = open_dir(settings.WHOOSH_INDEX)
NameError: global name 'open_dir' is not defined
2014-05-27 22:41:50,440 [ERROR] django.request: Internal Server Error: /articles/search/
Traceback (most recent call last):
  File "/home/damon/Documents/Python/django-damon/local/lib/python2.7/site-packages/Django-1.6.4-py2.7.egg/django/core/handlers/base.py", line 114, in get_response
    response = wrapped_callback(request, *callback_args, **callback_kwargs)
  File "/home/damon/Documents/Python/django-damon/django_test/article/views.py", line 26, in search_titles
    ix = open_dir(settings.WHOOSH_INDEX)
NameError: global name 'open_dir' is not defined
2014-05-27 22:41:50,565 [ERROR] django.request: Internal Server Error: /articles/search/
Traceback (most recent call last):
  File "/home/damon/Documents/Python/django-damon/local/lib/python2.7/site-packages/Django-1.6.4-py2.7.egg/django/core/handlers/base.py", line 114, in get_response
    response = wrapped_callback(request, *callback_args, **callback_kwargs)
  File "/home/damon/Documents/Python/django-damon/django_test/article/views.py", line 26, in search_titles
    ix = open_dir(settings.WHOOSH_INDEX)
NameError: global name 'open_dir' is not defined
2014-05-27 22:41:50,635 [ERROR] django.request: Internal Server Error: /articles/search/
Traceback (most recent call last):
  File "/home/damon/Documents/Python/django-damon/local/lib/python2.7/site-packages/Django-1.6.4-py2.7.egg/django/core/handlers/base.py", line 114, in get_response
    response = wrapped_callback(request, *callback_args, **callback_kwargs)
  File "/home/damon/Documents/Python/django-damon/django_test/article/views.py", line 26, in search_titles
    ix = open_dir(settings.WHOOSH_INDEX)
NameError: global name 'open_dir' is not defined
2014-05-27 22:41:51,054 [ERROR] django.request: Internal Server Error: /articles/search/
Traceback (most recent call last):
  File "/home/damon/Documents/Python/django-damon/local/lib/python2.7/site-packages/Django-1.6.4-py2.7.egg/django/core/handlers/base.py", line 114, in get_response
    response = wrapped_callback(request, *callback_args, **callback_kwargs)
  File "/home/damon/Documents/Python/django-damon/django_test/article/views.py", line 26, in search_titles
    ix = open_dir(settings.WHOOSH_INDEX)
NameError: global name 'open_dir' is not defined
2014-05-27 22:41:51,574 [ERROR] django.request: Internal Server Error: /articles/search/
Traceback (most recent call last):
  File "/home/damon/Documents/Python/django-damon/local/lib/python2.7/site-packages/Django-1.6.4-py2.7.egg/django/core/handlers/base.py", line 114, in get_response
    response = wrapped_callback(request, *callback_args, **callback_kwargs)
  File "/home/damon/Documents/Python/django-damon/django_test/article/views.py", line 26, in search_titles
    ix = open_dir(settings.WHOOSH_INDEX)
NameError: global name 'open_dir' is not defined
2014-05-27 22:41:51,805 [ERROR] django.request: Internal Server Error: /articles/search/
Traceback (most recent call last):
  File "/home/damon/Documents/Python/django-damon/local/lib/python2.7/site-packages/Django-1.6.4-py2.7.egg/django/core/handlers/base.py", line 114, in get_response
    response = wrapped_callback(request, *callback_args, **callback_kwargs)
  File "/home/damon/Documents/Python/django-damon/django_test/article/views.py", line 26, in search_titles
    ix = open_dir(settings.WHOOSH_INDEX)
NameError: global name 'open_dir' is not defined
2014-05-27 22:41:51,979 [ERROR] django.request: Internal Server Error: /articles/search/
Traceback (most recent call last):
  File "/home/damon/Documents/Python/django-damon/local/lib/python2.7/site-packages/Django-1.6.4-py2.7.egg/django/core/handlers/base.py", line 114, in get_response
    response = wrapped_callback(request, *callback_args, **callback_kwargs)
  File "/home/damon/Documents/Python/django-damon/django_test/article/views.py", line 26, in search_titles
    ix = open_dir(settings.WHOOSH_INDEX)
NameError: global name 'open_dir' is not defined
2014-05-27 22:41:52,160 [ERROR] django.request: Internal Server Error: /articles/search/
Traceback (most recent call last):
  File "/home/damon/Documents/Python/django-damon/local/lib/python2.7/site-packages/Django-1.6.4-py2.7.egg/django/core/handlers/base.py", line 114, in get_response
    response = wrapped_callback(request, *callback_args, **callback_kwargs)
  File "/home/damon/Documents/Python/django-damon/django_test/article/views.py", line 26, in search_titles
    ix = open_dir(settings.WHOOSH_INDEX)
NameError: global name 'open_dir' is not defined
2014-05-27 22:41:53,235 [ERROR] django.request: Internal Server Error: /articles/search/
Traceback (most recent call last):
  File "/home/damon/Documents/Python/django-damon/local/lib/python2.7/site-packages/Django-1.6.4-py2.7.egg/django/core/handlers/base.py", line 114, in get_response
    response = wrapped_callback(request, *callback_args, **callback_kwargs)
  File "/home/damon/Documents/Python/django-damon/django_test/article/views.py", line 26, in search_titles
    ix = open_dir(settings.WHOOSH_INDEX)
NameError: global name 'open_dir' is not defined
2014-05-27 22:41:55,456 [ERROR] django.request: Internal Server Error: /articles/search/
Traceback (most recent call last):
  File "/home/damon/Documents/Python/django-damon/local/lib/python2.7/site-packages/Django-1.6.4-py2.7.egg/django/core/handlers/base.py", line 114, in get_response
    response = wrapped_callback(request, *callback_args, **callback_kwargs)
  File "/home/damon/Documents/Python/django-damon/django_test/article/views.py", line 26, in search_titles
    ix = open_dir(settings.WHOOSH_INDEX)
NameError: global name 'open_dir' is not defined
2014-05-27 23:32:33,820 [ERROR] django.request: Internal Server Error: /articles/all/
Traceback (most recent call last):
  File "/home/damon/Documents/Python/django-damon/local/lib/python2.7/site-packages/Django-1.6.4-py2.7.egg/django/core/handlers/base.py", line 101, in get_response
    resolver_match = resolver.resolve(request.path_info)
  File "/home/damon/Documents/Python/django-damon/local/lib/python2.7/site-packages/Django-1.6.4-py2.7.egg/django/core/urlresolvers.py", line 337, in resolve
    for pattern in self.url_patterns:
  File "/home/damon/Documents/Python/django-damon/local/lib/python2.7/site-packages/Django-1.6.4-py2.7.egg/django/core/urlresolvers.py", line 365, in url_patterns
    patterns = getattr(self.urlconf_module, "urlpatterns", self.urlconf_module)
  File "/home/damon/Documents/Python/django-damon/local/lib/python2.7/site-packages/Django-1.6.4-py2.7.egg/django/core/urlresolvers.py", line 360, in urlconf_module
    self._urlconf_module = import_module(self.urlconf_name)
  File "/home/damon/Documents/Python/django-damon/local/lib/python2.7/site-packages/Django-1.6.4-py2.7.egg/django/utils/importlib.py", line 40, in import_module
    __import__(name)
  File "/home/damon/Documents/Python/django-damon/django_test/django_test/urls.py", line 2, in <module>
    from article.views import HelloTemplate
  File "/home/damon/Documents/Python/django-damon/django_test/article/views.py", line 11, in <module>
    from haystack.query import SearchQuerySet
ImportError: No module named haystack.query
2014-05-27 23:32:34,444 [ERROR] django.request: Internal Server Error: /favicon.ico
Traceback (most recent call last):
  File "/home/damon/Documents/Python/django-damon/local/lib/python2.7/site-packages/Django-1.6.4-py2.7.egg/django/core/handlers/base.py", line 90, in get_response
    response = middleware_method(request)
  File "/home/damon/Documents/Python/django-damon/local/lib/python2.7/site-packages/Django-1.6.4-py2.7.egg/django/middleware/common.py", line 71, in process_request
    if (not urlresolvers.is_valid_path(request.path_info, urlconf) and
  File "/home/damon/Documents/Python/django-damon/local/lib/python2.7/site-packages/Django-1.6.4-py2.7.egg/django/core/urlresolvers.py", line 596, in is_valid_path
    resolve(path, urlconf)
  File "/home/damon/Documents/Python/django-damon/local/lib/python2.7/site-packages/Django-1.6.4-py2.7.egg/django/core/urlresolvers.py", line 476, in resolve
    return get_resolver(urlconf).resolve(path)
  File "/home/damon/Documents/Python/django-damon/local/lib/python2.7/site-packages/Django-1.6.4-py2.7.egg/django/core/urlresolvers.py", line 337, in resolve
    for pattern in self.url_patterns:
  File "/home/damon/Documents/Python/django-damon/local/lib/python2.7/site-packages/Django-1.6.4-py2.7.egg/django/core/urlresolvers.py", line 365, in url_patterns
    patterns = getattr(self.urlconf_module, "urlpatterns", self.urlconf_module)
  File "/home/damon/Documents/Python/django-damon/local/lib/python2.7/site-packages/Django-1.6.4-py2.7.egg/django/core/urlresolvers.py", line 360, in urlconf_module
    self._urlconf_module = import_module(self.urlconf_name)
  File "/home/damon/Documents/Python/django-damon/local/lib/python2.7/site-packages/Django-1.6.4-py2.7.egg/django/utils/importlib.py", line 40, in import_module
    __import__(name)
  File "/home/damon/Documents/Python/django-damon/django_test/django_test/urls.py", line 2, in <module>
    from article.views import HelloTemplate
  File "/home/damon/Documents/Python/django-damon/django_test/article/views.py", line 11, in <module>
    from haystack.query import SearchQuerySet
ImportError: No module named haystack.query
2014-05-27 23:32:57,939 [ERROR] django.request: Internal Server Error: /articles/all/
Traceback (most recent call last):
  File "/home/damon/Documents/Python/django-damon/local/lib/python2.7/site-packages/Django-1.6.4-py2.7.egg/django/core/handlers/base.py", line 101, in get_response
    resolver_match = resolver.resolve(request.path_info)
  File "/home/damon/Documents/Python/django-damon/local/lib/python2.7/site-packages/Django-1.6.4-py2.7.egg/django/core/urlresolvers.py", line 337, in resolve
    for pattern in self.url_patterns:
  File "/home/damon/Documents/Python/django-damon/local/lib/python2.7/site-packages/Django-1.6.4-py2.7.egg/django/core/urlresolvers.py", line 365, in url_patterns
    patterns = getattr(self.urlconf_module, "urlpatterns", self.urlconf_module)
  File "/home/damon/Documents/Python/django-damon/local/lib/python2.7/site-packages/Django-1.6.4-py2.7.egg/django/core/urlresolvers.py", line 360, in urlconf_module
    self._urlconf_module = import_module(self.urlconf_name)
  File "/home/damon/Documents/Python/django-damon/local/lib/python2.7/site-packages/Django-1.6.4-py2.7.egg/django/utils/importlib.py", line 40, in import_module
    __import__(name)
  File "/home/damon/Documents/Python/django-damon/django_test/django_test/urls.py", line 2, in <module>
    from article.views import HelloTemplate
  File "/home/damon/Documents/Python/django-damon/django_test/article/views.py", line 12, in <module>
    from whoosh.index import open_dir
ImportError: No module named whoosh.index
2014-05-27 23:32:58,411 [ERROR] django.request: Internal Server Error: /favicon.ico
Traceback (most recent call last):
  File "/home/damon/Documents/Python/django-damon/local/lib/python2.7/site-packages/Django-1.6.4-py2.7.egg/django/core/handlers/base.py", line 90, in get_response
    response = middleware_method(request)
  File "/home/damon/Documents/Python/django-damon/local/lib/python2.7/site-packages/Django-1.6.4-py2.7.egg/django/middleware/common.py", line 71, in process_request
    if (not urlresolvers.is_valid_path(request.path_info, urlconf) and
  File "/home/damon/Documents/Python/django-damon/local/lib/python2.7/site-packages/Django-1.6.4-py2.7.egg/django/core/urlresolvers.py", line 596, in is_valid_path
    resolve(path, urlconf)
  File "/home/damon/Documents/Python/django-damon/local/lib/python2.7/site-packages/Django-1.6.4-py2.7.egg/django/core/urlresolvers.py", line 476, in resolve
    return get_resolver(urlconf).resolve(path)
  File "/home/damon/Documents/Python/django-damon/local/lib/python2.7/site-packages/Django-1.6.4-py2.7.egg/django/core/urlresolvers.py", line 337, in resolve
    for pattern in self.url_patterns:
  File "/home/damon/Documents/Python/django-damon/local/lib/python2.7/site-packages/Django-1.6.4-py2.7.egg/django/core/urlresolvers.py", line 365, in url_patterns
    patterns = getattr(self.urlconf_module, "urlpatterns", self.urlconf_module)
  File "/home/damon/Documents/Python/django-damon/local/lib/python2.7/site-packages/Django-1.6.4-py2.7.egg/django/core/urlresolvers.py", line 360, in urlconf_module
    self._urlconf_module = import_module(self.urlconf_name)
  File "/home/damon/Documents/Python/django-damon/local/lib/python2.7/site-packages/Django-1.6.4-py2.7.egg/django/utils/importlib.py", line 40, in import_module
    __import__(name)
  File "/home/damon/Documents/Python/django-damon/django_test/django_test/urls.py", line 2, in <module>
    from article.views import HelloTemplate
  File "/home/damon/Documents/Python/django-damon/django_test/article/views.py", line 12, in <module>
    from whoosh.index import open_dir
ImportError: No module named whoosh.index
2014-05-27 23:37:28,621 [ERROR] django.request: Internal Server Error: /articles/all/
Traceback (most recent call last):
  File "/home/damon/Documents/Python/django-damon/local/lib/python2.7/site-packages/Django-1.6.4-py2.7.egg/django/core/handlers/base.py", line 101, in get_response
    resolver_match = resolver.resolve(request.path_info)
  File "/home/damon/Documents/Python/django-damon/local/lib/python2.7/site-packages/Django-1.6.4-py2.7.egg/django/core/urlresolvers.py", line 337, in resolve
    for pattern in self.url_patterns:
  File "/home/damon/Documents/Python/django-damon/local/lib/python2.7/site-packages/Django-1.6.4-py2.7.egg/django/core/urlresolvers.py", line 365, in url_patterns
    patterns = getattr(self.urlconf_module, "urlpatterns", self.urlconf_module)
  File "/home/damon/Documents/Python/django-damon/local/lib/python2.7/site-packages/Django-1.6.4-py2.7.egg/django/core/urlresolvers.py", line 360, in urlconf_module
    self._urlconf_module = import_module(self.urlconf_name)
  File "/home/damon/Documents/Python/django-damon/local/lib/python2.7/site-packages/Django-1.6.4-py2.7.egg/django/utils/importlib.py", line 40, in import_module
    __import__(name)
  File "/home/damon/Documents/Python/django-damon/django_test/django_test/urls.py", line 2, in <module>
    from article.views import HelloTemplate
  File "/home/damon/Documents/Python/django-damon/django_test/article/views.py", line 12, in <module>
    from whoosh.index import open_dir
ImportError: No module named whoosh.index
2014-05-27 23:37:29,015 [ERROR] django.request: Internal Server Error: /favicon.ico
Traceback (most recent call last):
  File "/home/damon/Documents/Python/django-damon/local/lib/python2.7/site-packages/Django-1.6.4-py2.7.egg/django/core/handlers/base.py", line 90, in get_response
    response = middleware_method(request)
  File "/home/damon/Documents/Python/django-damon/local/lib/python2.7/site-packages/Django-1.6.4-py2.7.egg/django/middleware/common.py", line 71, in process_request
    if (not urlresolvers.is_valid_path(request.path_info, urlconf) and
  File "/home/damon/Documents/Python/django-damon/local/lib/python2.7/site-packages/Django-1.6.4-py2.7.egg/django/core/urlresolvers.py", line 596, in is_valid_path
    resolve(path, urlconf)
  File "/home/damon/Documents/Python/django-damon/local/lib/python2.7/site-packages/Django-1.6.4-py2.7.egg/django/core/urlresolvers.py", line 476, in resolve
    return get_resolver(urlconf).resolve(path)
  File "/home/damon/Documents/Python/django-damon/local/lib/python2.7/site-packages/Django-1.6.4-py2.7.egg/django/core/urlresolvers.py", line 337, in resolve
    for pattern in self.url_patterns:
  File "/home/damon/Documents/Python/django-damon/local/lib/python2.7/site-packages/Django-1.6.4-py2.7.egg/django/core/urlresolvers.py", line 365, in url_patterns
    patterns = getattr(self.urlconf_module, "urlpatterns", self.urlconf_module)
  File "/home/damon/Documents/Python/django-damon/local/lib/python2.7/site-packages/Django-1.6.4-py2.7.egg/django/core/urlresolvers.py", line 360, in urlconf_module
    self._urlconf_module = import_module(self.urlconf_name)
  File "/home/damon/Documents/Python/django-damon/local/lib/python2.7/site-packages/Django-1.6.4-py2.7.egg/django/utils/importlib.py", line 40, in import_module
    __import__(name)
  File "/home/damon/Documents/Python/django-damon/django_test/django_test/urls.py", line 2, in <module>
    from article.views import HelloTemplate
  File "/home/damon/Documents/Python/django-damon/django_test/article/views.py", line 12, in <module>
    from whoosh.index import open_dir
ImportError: No module named whoosh.index
2014-05-27 23:37:45,916 [WARNING] django.request: Not Found: /favicon.ico
2014-05-28 04:24:16,033 [ERROR] django.request: Internal Server Error: /articles/all/
Traceback (most recent call last):
  File "/home/damon/Documents/Python/django-damon/local/lib/python2.7/site-packages/Django-1.6.4-py2.7.egg/django/core/handlers/base.py", line 101, in get_response
    resolver_match = resolver.resolve(request.path_info)
  File "/home/damon/Documents/Python/django-damon/local/lib/python2.7/site-packages/Django-1.6.4-py2.7.egg/django/core/urlresolvers.py", line 337, in resolve
    for pattern in self.url_patterns:
  File "/home/damon/Documents/Python/django-damon/local/lib/python2.7/site-packages/Django-1.6.4-py2.7.egg/django/core/urlresolvers.py", line 365, in url_patterns
    patterns = getattr(self.urlconf_module, "urlpatterns", self.urlconf_module)
  File "/home/damon/Documents/Python/django-damon/local/lib/python2.7/site-packages/Django-1.6.4-py2.7.egg/django/core/urlresolvers.py", line 360, in urlconf_module
    self._urlconf_module = import_module(self.urlconf_name)
  File "/home/damon/Documents/Python/django-damon/local/lib/python2.7/site-packages/Django-1.6.4-py2.7.egg/django/utils/importlib.py", line 40, in import_module
    __import__(name)
  File "/home/damon/Documents/Python/django-damon/django_test/django_test/urls.py", line 8, in <module>
    from django_test.forms import ContactWizard
ImportError: cannot import name ContactWizard
2014-05-28 04:24:21,807 [ERROR] django.request: Internal Server Error: /contact
Traceback (most recent call last):
  File "/home/damon/Documents/Python/django-damon/local/lib/python2.7/site-packages/Django-1.6.4-py2.7.egg/django/core/handlers/base.py", line 90, in get_response
    response = middleware_method(request)
  File "/home/damon/Documents/Python/django-damon/local/lib/python2.7/site-packages/Django-1.6.4-py2.7.egg/django/middleware/common.py", line 71, in process_request
    if (not urlresolvers.is_valid_path(request.path_info, urlconf) and
  File "/home/damon/Documents/Python/django-damon/local/lib/python2.7/site-packages/Django-1.6.4-py2.7.egg/django/core/urlresolvers.py", line 596, in is_valid_path
    resolve(path, urlconf)
  File "/home/damon/Documents/Python/django-damon/local/lib/python2.7/site-packages/Django-1.6.4-py2.7.egg/django/core/urlresolvers.py", line 476, in resolve
    return get_resolver(urlconf).resolve(path)
  File "/home/damon/Documents/Python/django-damon/local/lib/python2.7/site-packages/Django-1.6.4-py2.7.egg/django/core/urlresolvers.py", line 337, in resolve
    for pattern in self.url_patterns:
  File "/home/damon/Documents/Python/django-damon/local/lib/python2.7/site-packages/Django-1.6.4-py2.7.egg/django/core/urlresolvers.py", line 365, in url_patterns
    patterns = getattr(self.urlconf_module, "urlpatterns", self.urlconf_module)
  File "/home/damon/Documents/Python/django-damon/local/lib/python2.7/site-packages/Django-1.6.4-py2.7.egg/django/core/urlresolvers.py", line 360, in urlconf_module
    self._urlconf_module = import_module(self.urlconf_name)
  File "/home/damon/Documents/Python/django-damon/local/lib/python2.7/site-packages/Django-1.6.4-py2.7.egg/django/utils/importlib.py", line 40, in import_module
    __import__(name)
  File "/home/damon/Documents/Python/django-damon/django_test/django_test/urls.py", line 8, in <module>
    from django_test.forms import ContactWizard
ImportError: cannot import name ContactWizard
2014-05-28 14:33:22,272 [ERROR] django.request: Internal Server Error: /contact/
Traceback (most recent call last):
  File "/home/damon/Documents/Python/django-damon/local/lib/python2.7/site-packages/Django-1.6.4-py2.7.egg/django/core/handlers/base.py", line 114, in get_response
    response = wrapped_callback(request, *callback_args, **callback_kwargs)
  File "/home/damon/Documents/Python/django-damon/local/lib/python2.7/site-packages/Django-1.6.4-py2.7.egg/django/views/generic/base.py", line 69, in view
    return self.dispatch(request, *args, **kwargs)
  File "/home/damon/Documents/Python/django-damon/local/lib/python2.7/site-packages/Django-1.6.4-py2.7.egg/django/contrib/formtools/wizard/views.py", line 236, in dispatch
    response = super(WizardView, self).dispatch(request, *args, **kwargs)
  File "/home/damon/Documents/Python/django-damon/local/lib/python2.7/site-packages/Django-1.6.4-py2.7.egg/django/views/generic/base.py", line 87, in dispatch
    return handler(request, *args, **kwargs)
  File "/home/damon/Documents/Python/django-damon/local/lib/python2.7/site-packages/Django-1.6.4-py2.7.egg/django/contrib/formtools/wizard/views.py", line 297, in post
    return self.render_done(form, **kwargs)
  File "/home/damon/Documents/Python/django-damon/local/lib/python2.7/site-packages/Django-1.6.4-py2.7.egg/django/contrib/formtools/wizard/views.py", line 350, in render_done
    done_response = self.done(final_form_list, **kwargs)
  File "/home/damon/Documents/Python/django-damon/django_test/django_test/views.py", line 62, in done
    form_data = process_form_data(form_list)
  File "/home/damon/Documents/Python/django-damon/django_test/django_test/views.py", line 75, in process_form_data
    ['zhangbin@gwmail.gwu.edu'],fail_silently=False)
  File "/home/damon/Documents/Python/django-damon/local/lib/python2.7/site-packages/Django-1.6.4-py2.7.egg/django/core/mail/__init__.py", line 50, in send_mail
    connection=connection).send()
  File "/home/damon/Documents/Python/django-damon/local/lib/python2.7/site-packages/Django-1.6.4-py2.7.egg/django/core/mail/message.py", line 274, in send
    return self.get_connection(fail_silently).send_messages([self])
  File "/home/damon/Documents/Python/django-damon/local/lib/python2.7/site-packages/Django-1.6.4-py2.7.egg/django/core/mail/backends/smtp.py", line 87, in send_messages
    new_conn_created = self.open()
  File "/home/damon/Documents/Python/django-damon/local/lib/python2.7/site-packages/Django-1.6.4-py2.7.egg/django/core/mail/backends/smtp.py", line 48, in open
    local_hostname=DNS_NAME.get_fqdn())
  File "/usr/lib/python2.7/smtplib.py", line 249, in __init__
    (code, msg) = self.connect(host, port)
  File "/usr/lib/python2.7/smtplib.py", line 309, in connect
    self.sock = self._get_socket(host, port, self.timeout)
  File "/usr/lib/python2.7/smtplib.py", line 284, in _get_socket
    return socket.create_connection((port, host), timeout)
  File "/usr/lib/python2.7/socket.py", line 571, in create_connection
    raise err
error: [Errno 111] Connection refused
2014-05-28 14:34:28,422 [ERROR] django.request: Internal Server Error: /contact/
Traceback (most recent call last):
  File "/home/damon/Documents/Python/django-damon/local/lib/python2.7/site-packages/Django-1.6.4-py2.7.egg/django/core/handlers/base.py", line 114, in get_response
    response = wrapped_callback(request, *callback_args, **callback_kwargs)
  File "/home/damon/Documents/Python/django-damon/local/lib/python2.7/site-packages/Django-1.6.4-py2.7.egg/django/views/generic/base.py", line 69, in view
    return self.dispatch(request, *args, **kwargs)
  File "/home/damon/Documents/Python/django-damon/local/lib/python2.7/site-packages/Django-1.6.4-py2.7.egg/django/contrib/formtools/wizard/views.py", line 236, in dispatch
    response = super(WizardView, self).dispatch(request, *args, **kwargs)
  File "/home/damon/Documents/Python/django-damon/local/lib/python2.7/site-packages/Django-1.6.4-py2.7.egg/django/views/generic/base.py", line 87, in dispatch
    return handler(request, *args, **kwargs)
  File "/home/damon/Documents/Python/django-damon/local/lib/python2.7/site-packages/Django-1.6.4-py2.7.egg/django/contrib/formtools/wizard/views.py", line 297, in post
    return self.render_done(form, **kwargs)
  File "/home/damon/Documents/Python/django-damon/local/lib/python2.7/site-packages/Django-1.6.4-py2.7.egg/django/contrib/formtools/wizard/views.py", line 350, in render_done
    done_response = self.done(final_form_list, **kwargs)
  File "/home/damon/Documents/Python/django-damon/django_test/django_test/views.py", line 62, in done
    form_data = process_form_data(form_list)
  File "/home/damon/Documents/Python/django-damon/django_test/django_test/views.py", line 75, in process_form_data
    ['zhangbin@gwmail.gwu.edu'],fail_silently=False)
  File "/home/damon/Documents/Python/django-damon/local/lib/python2.7/site-packages/Django-1.6.4-py2.7.egg/django/core/mail/__init__.py", line 50, in send_mail
    connection=connection).send()
  File "/home/damon/Documents/Python/django-damon/local/lib/python2.7/site-packages/Django-1.6.4-py2.7.egg/django/core/mail/message.py", line 274, in send
    return self.get_connection(fail_silently).send_messages([self])
  File "/home/damon/Documents/Python/django-damon/local/lib/python2.7/site-packages/Django-1.6.4-py2.7.egg/django/core/mail/backends/smtp.py", line 87, in send_messages
    new_conn_created = self.open()
  File "/home/damon/Documents/Python/django-damon/local/lib/python2.7/site-packages/Django-1.6.4-py2.7.egg/django/core/mail/backends/smtp.py", line 48, in open
    local_hostname=DNS_NAME.get_fqdn())
  File "/usr/lib/python2.7/smtplib.py", line 249, in __init__
    (code, msg) = self.connect(host, port)
  File "/usr/lib/python2.7/smtplib.py", line 309, in connect
    self.sock = self._get_socket(host, port, self.timeout)
  File "/usr/lib/python2.7/smtplib.py", line 284, in _get_socket
    return socket.create_connection((port, host), timeout)
  File "/usr/lib/python2.7/socket.py", line 571, in create_connection
    raise err
error: [Errno 111] Connection refused
2014-05-28 18:40:17,599 [WARNING] django.request: Not Found: /accounts/profile
2014-05-28 18:40:54,306 [ERROR] django.request: Internal Server Error: /accounts/profile
Traceback (most recent call last):
  File "/home/damon/Documents/Python/django-damon/local/lib/python2.7/site-packages/Django-1.6.4-py2.7.egg/django/core/handlers/base.py", line 90, in get_response
    response = middleware_method(request)
  File "/home/damon/Documents/Python/django-damon/local/lib/python2.7/site-packages/Django-1.6.4-py2.7.egg/django/middleware/common.py", line 72, in process_request
    urlresolvers.is_valid_path("%s/" % request.path_info, urlconf)):
  File "/home/damon/Documents/Python/django-damon/local/lib/python2.7/site-packages/Django-1.6.4-py2.7.egg/django/core/urlresolvers.py", line 596, in is_valid_path
    resolve(path, urlconf)
  File "/home/damon/Documents/Python/django-damon/local/lib/python2.7/site-packages/Django-1.6.4-py2.7.egg/django/core/urlresolvers.py", line 476, in resolve
    return get_resolver(urlconf).resolve(path)
  File "/home/damon/Documents/Python/django-damon/local/lib/python2.7/site-packages/Django-1.6.4-py2.7.egg/django/core/urlresolvers.py", line 339, in resolve
    sub_match = pattern.resolve(new_path)
  File "/home/damon/Documents/Python/django-damon/local/lib/python2.7/site-packages/Django-1.6.4-py2.7.egg/django/core/urlresolvers.py", line 339, in resolve
    sub_match = pattern.resolve(new_path)
  File "/home/damon/Documents/Python/django-damon/local/lib/python2.7/site-packages/Django-1.6.4-py2.7.egg/django/core/urlresolvers.py", line 223, in resolve
    return ResolverMatch(self.callback, args, kwargs, self.name)
  File "/home/damon/Documents/Python/django-damon/local/lib/python2.7/site-packages/Django-1.6.4-py2.7.egg/django/core/urlresolvers.py", line 230, in callback
    self._callback = get_callable(self._callback_str)
  File "/home/damon/Documents/Python/django-damon/local/lib/python2.7/site-packages/Django-1.6.4-py2.7.egg/django/utils/functional.py", line 32, in wrapper
    result = func(*args)
  File "/home/damon/Documents/Python/django-damon/local/lib/python2.7/site-packages/Django-1.6.4-py2.7.egg/django/core/urlresolvers.py", line 97, in get_callable
    mod = import_module(mod_name)
  File "/home/damon/Documents/Python/django-damon/local/lib/python2.7/site-packages/Django-1.6.4-py2.7.egg/django/utils/importlib.py", line 40, in import_module
    __import__(name)
  File "/home/damon/Documents/Python/django-damon/django_test/userprofile/views.py", line 13
    from.save()
             ^
SyntaxError: invalid syntax
2014-05-28 18:41:27,884 [ERROR] django.request: Internal Server Error: /accounts/profile
Traceback (most recent call last):
  File "/home/damon/Documents/Python/django-damon/local/lib/python2.7/site-packages/Django-1.6.4-py2.7.egg/django/core/handlers/base.py", line 90, in get_response
    response = middleware_method(request)
  File "/home/damon/Documents/Python/django-damon/local/lib/python2.7/site-packages/Django-1.6.4-py2.7.egg/django/middleware/common.py", line 72, in process_request
    urlresolvers.is_valid_path("%s/" % request.path_info, urlconf)):
  File "/home/damon/Documents/Python/django-damon/local/lib/python2.7/site-packages/Django-1.6.4-py2.7.egg/django/core/urlresolvers.py", line 596, in is_valid_path
    resolve(path, urlconf)
  File "/home/damon/Documents/Python/django-damon/local/lib/python2.7/site-packages/Django-1.6.4-py2.7.egg/django/core/urlresolvers.py", line 476, in resolve
    return get_resolver(urlconf).resolve(path)
  File "/home/damon/Documents/Python/django-damon/local/lib/python2.7/site-packages/Django-1.6.4-py2.7.egg/django/core/urlresolvers.py", line 339, in resolve
    sub_match = pattern.resolve(new_path)
  File "/home/damon/Documents/Python/django-damon/local/lib/python2.7/site-packages/Django-1.6.4-py2.7.egg/django/core/urlresolvers.py", line 339, in resolve
    sub_match = pattern.resolve(new_path)
  File "/home/damon/Documents/Python/django-damon/local/lib/python2.7/site-packages/Django-1.6.4-py2.7.egg/django/core/urlresolvers.py", line 223, in resolve
    return ResolverMatch(self.callback, args, kwargs, self.name)
  File "/home/damon/Documents/Python/django-damon/local/lib/python2.7/site-packages/Django-1.6.4-py2.7.egg/django/core/urlresolvers.py", line 230, in callback
    self._callback = get_callable(self._callback_str)
  File "/home/damon/Documents/Python/django-damon/local/lib/python2.7/site-packages/Django-1.6.4-py2.7.egg/django/utils/functional.py", line 32, in wrapper
    result = func(*args)
  File "/home/damon/Documents/Python/django-damon/local/lib/python2.7/site-packages/Django-1.6.4-py2.7.egg/django/core/urlresolvers.py", line 97, in get_callable
    mod = import_module(mod_name)
  File "/home/damon/Documents/Python/django-damon/local/lib/python2.7/site-packages/Django-1.6.4-py2.7.egg/django/utils/importlib.py", line 40, in import_module
    __import__(name)
  File "/home/damon/Documents/Python/django-damon/django_test/userprofile/views.py", line 4, in <module>
    from forms import UserProfileForm
  File "/home/damon/Documents/Python/django-damon/django_test/userprofile/forms.py", line 4, in <module>
    class UserProfileForm(forms.ModelForm):
  File "/home/damon/Documents/Python/django-damon/local/lib/python2.7/site-packages/Django-1.6.4-py2.7.egg/django/forms/models.py", line 292, in __new__
    raise FieldError(message)
FieldError: Unknown field(s) (fabourite_hamster_name) specified for UserProfile
2014-05-28 18:42:14,783 [ERROR] django.request: Internal Server Error: /accounts/profile/
Traceback (most recent call last):
  File "/home/damon/Documents/Python/django-damon/local/lib/python2.7/site-packages/Django-1.6.4-py2.7.egg/django/core/handlers/base.py", line 114, in get_response
    response = wrapped_callback(request, *callback_args, **callback_kwargs)
  File "/home/damon/Documents/Python/django-damon/local/lib/python2.7/site-packages/Django-1.6.4-py2.7.egg/django/contrib/auth/decorators.py", line 22, in _wrapped_view
    return view_func(request, *args, **kwargs)
  File "/home/damon/Documents/Python/django-damon/django_test/userprofile/views.py", line 17, in user_profile
    profile = user.profile
  File "/home/damon/Documents/Python/django-damon/local/lib/python2.7/site-packages/Django-1.6.4-py2.7.egg/django/utils/functional.py", line 214, in inner
    return func(self._wrapped, *args)
  File "/home/damon/Documents/Python/django-damon/django_test/userprofile/models.py", line 11, in <lambda>
    User.profile = property(lambda u:UserProfile.objects.get_or_create(user=u)[0])
  File "/home/damon/Documents/Python/django-damon/local/lib/python2.7/site-packages/Django-1.6.4-py2.7.egg/django/db/models/manager.py", line 154, in get_or_create
    return self.get_queryset().get_or_create(**kwargs)
  File "/home/damon/Documents/Python/django-damon/local/lib/python2.7/site-packages/Django-1.6.4-py2.7.egg/django/db/models/query.py", line 388, in get_or_create
    six.reraise(*exc_info)
  File "/home/damon/Documents/Python/django-damon/local/lib/python2.7/site-packages/Django-1.6.4-py2.7.egg/django/db/models/query.py", line 380, in get_or_create
    obj.save(force_insert=True, using=self.db)
  File "/home/damon/Documents/Python/django-damon/local/lib/python2.7/site-packages/Django-1.6.4-py2.7.egg/django/db/models/base.py", line 545, in save
    force_update=force_update, update_fields=update_fields)
  File "/home/damon/Documents/Python/django-damon/local/lib/python2.7/site-packages/Django-1.6.4-py2.7.egg/django/db/models/base.py", line 573, in save_base
    updated = self._save_table(raw, cls, force_insert, force_update, using, update_fields)
  File "/home/damon/Documents/Python/django-damon/local/lib/python2.7/site-packages/Django-1.6.4-py2.7.egg/django/db/models/base.py", line 654, in _save_table
    result = self._do_insert(cls._base_manager, using, fields, update_pk, raw)
  File "/home/damon/Documents/Python/django-damon/local/lib/python2.7/site-packages/Django-1.6.4-py2.7.egg/django/db/models/base.py", line 687, in _do_insert
    using=using, raw=raw)
  File "/home/damon/Documents/Python/django-damon/local/lib/python2.7/site-packages/Django-1.6.4-py2.7.egg/django/db/models/manager.py", line 232, in _insert
    return insert_query(self.model, objs, fields, **kwargs)
  File "/home/damon/Documents/Python/django-damon/local/lib/python2.7/site-packages/Django-1.6.4-py2.7.egg/django/db/models/query.py", line 1511, in insert_query
    return query.get_compiler(using=using).execute_sql(return_id)
  File "/home/damon/Documents/Python/django-damon/local/lib/python2.7/site-packages/Django-1.6.4-py2.7.egg/django/db/models/sql/compiler.py", line 903, in execute_sql
    cursor.execute(sql, params)
  File "/home/damon/Documents/Python/django-damon/local/lib/python2.7/site-packages/Django-1.6.4-py2.7.egg/django/db/backends/util.py", line 69, in execute
    return super(CursorDebugWrapper, self).execute(sql, params)
  File "/home/damon/Documents/Python/django-damon/local/lib/python2.7/site-packages/Django-1.6.4-py2.7.egg/django/db/backends/util.py", line 53, in execute
    return self.cursor.execute(sql, params)
  File "/home/damon/Documents/Python/django-damon/local/lib/python2.7/site-packages/Django-1.6.4-py2.7.egg/django/db/backends/mysql/base.py", line 129, in execute
    six.reraise(utils.IntegrityError, utils.IntegrityError(*tuple(e.args)), sys.exc_info()[2])
  File "/home/damon/Documents/Python/django-damon/local/lib/python2.7/site-packages/Django-1.6.4-py2.7.egg/django/db/backends/mysql/base.py", line 124, in execute
    return self.cursor.execute(query, args)
  File "/home/damon/Documents/Python/django-damon/local/lib/python2.7/site-packages/MySQL_python-1.2.5-py2.7-linux-x86_64.egg/MySQLdb/cursors.py", line 205, in execute
    self.errorhandler(self, exc, value)
  File "/home/damon/Documents/Python/django-damon/local/lib/python2.7/site-packages/MySQL_python-1.2.5-py2.7-linux-x86_64.egg/MySQLdb/connections.py", line 36, in defaulterrorhandler
    raise errorclass, errorvalue
IntegrityError: (1048, "Column 'likes_cheese' cannot be null")
2014-05-28 18:54:01,303 [ERROR] django.request: Internal Server Error: /accounts/profile/
Traceback (most recent call last):
  File "/home/damon/Documents/Python/django-damon/local/lib/python2.7/site-packages/Django-1.6.4-py2.7.egg/django/core/handlers/base.py", line 114, in get_response
    response = wrapped_callback(request, *callback_args, **callback_kwargs)
  File "/home/damon/Documents/Python/django-damon/local/lib/python2.7/site-packages/Django-1.6.4-py2.7.egg/django/contrib/auth/decorators.py", line 22, in _wrapped_view
    return view_func(request, *args, **kwargs)
  File "/home/damon/Documents/Python/django-damon/django_test/userprofile/views.py", line 17, in user_profile
    profile = user.profile
  File "/home/damon/Documents/Python/django-damon/local/lib/python2.7/site-packages/Django-1.6.4-py2.7.egg/django/utils/functional.py", line 214, in inner
    return func(self._wrapped, *args)
  File "/home/damon/Documents/Python/django-damon/django_test/userprofile/models.py", line 11, in <lambda>
    User.profile = property(lambda u:UserProfile.objects.get_or_create(user=u)[0])
  File "/home/damon/Documents/Python/django-damon/local/lib/python2.7/site-packages/Django-1.6.4-py2.7.egg/django/db/models/manager.py", line 154, in get_or_create
    return self.get_queryset().get_or_create(**kwargs)
  File "/home/damon/Documents/Python/django-damon/local/lib/python2.7/site-packages/Django-1.6.4-py2.7.egg/django/db/models/query.py", line 388, in get_or_create
    six.reraise(*exc_info)
  File "/home/damon/Documents/Python/django-damon/local/lib/python2.7/site-packages/Django-1.6.4-py2.7.egg/django/db/models/query.py", line 380, in get_or_create
    obj.save(force_insert=True, using=self.db)
  File "/home/damon/Documents/Python/django-damon/local/lib/python2.7/site-packages/Django-1.6.4-py2.7.egg/django/db/models/base.py", line 545, in save
    force_update=force_update, update_fields=update_fields)
  File "/home/damon/Documents/Python/django-damon/local/lib/python2.7/site-packages/Django-1.6.4-py2.7.egg/django/db/models/base.py", line 573, in save_base
    updated = self._save_table(raw, cls, force_insert, force_update, using, update_fields)
  File "/home/damon/Documents/Python/django-damon/local/lib/python2.7/site-packages/Django-1.6.4-py2.7.egg/django/db/models/base.py", line 654, in _save_table
    result = self._do_insert(cls._base_manager, using, fields, update_pk, raw)
  File "/home/damon/Documents/Python/django-damon/local/lib/python2.7/site-packages/Django-1.6.4-py2.7.egg/django/db/models/base.py", line 687, in _do_insert
    using=using, raw=raw)
  File "/home/damon/Documents/Python/django-damon/local/lib/python2.7/site-packages/Django-1.6.4-py2.7.egg/django/db/models/manager.py", line 232, in _insert
    return insert_query(self.model, objs, fields, **kwargs)
  File "/home/damon/Documents/Python/django-damon/local/lib/python2.7/site-packages/Django-1.6.4-py2.7.egg/django/db/models/query.py", line 1511, in insert_query
    return query.get_compiler(using=using).execute_sql(return_id)
  File "/home/damon/Documents/Python/django-damon/local/lib/python2.7/site-packages/Django-1.6.4-py2.7.egg/django/db/models/sql/compiler.py", line 903, in execute_sql
    cursor.execute(sql, params)
  File "/home/damon/Documents/Python/django-damon/local/lib/python2.7/site-packages/Django-1.6.4-py2.7.egg/django/db/backends/util.py", line 69, in execute
    return super(CursorDebugWrapper, self).execute(sql, params)
  File "/home/damon/Documents/Python/django-damon/local/lib/python2.7/site-packages/Django-1.6.4-py2.7.egg/django/db/backends/util.py", line 53, in execute
    return self.cursor.execute(sql, params)
  File "/home/damon/Documents/Python/django-damon/local/lib/python2.7/site-packages/Django-1.6.4-py2.7.egg/django/db/backends/mysql/base.py", line 129, in execute
    six.reraise(utils.IntegrityError, utils.IntegrityError(*tuple(e.args)), sys.exc_info()[2])
  File "/home/damon/Documents/Python/django-damon/local/lib/python2.7/site-packages/Django-1.6.4-py2.7.egg/django/db/backends/mysql/base.py", line 124, in execute
    return self.cursor.execute(query, args)
  File "/home/damon/Documents/Python/django-damon/local/lib/python2.7/site-packages/MySQL_python-1.2.5-py2.7-linux-x86_64.egg/MySQLdb/cursors.py", line 205, in execute
    self.errorhandler(self, exc, value)
  File "/home/damon/Documents/Python/django-damon/local/lib/python2.7/site-packages/MySQL_python-1.2.5-py2.7-linux-x86_64.egg/MySQLdb/connections.py", line 36, in defaulterrorhandler
    raise errorclass, errorvalue
IntegrityError: (1048, "Column 'likes_cheese' cannot be null")
2014-05-28 18:54:03,441 [ERROR] django.request: Internal Server Error: /accounts/profile/
Traceback (most recent call last):
  File "/home/damon/Documents/Python/django-damon/local/lib/python2.7/site-packages/Django-1.6.4-py2.7.egg/django/core/handlers/base.py", line 114, in get_response
    response = wrapped_callback(request, *callback_args, **callback_kwargs)
  File "/home/damon/Documents/Python/django-damon/local/lib/python2.7/site-packages/Django-1.6.4-py2.7.egg/django/contrib/auth/decorators.py", line 22, in _wrapped_view
    return view_func(request, *args, **kwargs)
  File "/home/damon/Documents/Python/django-damon/django_test/userprofile/views.py", line 17, in user_profile
    profile = user.profile
  File "/home/damon/Documents/Python/django-damon/local/lib/python2.7/site-packages/Django-1.6.4-py2.7.egg/django/utils/functional.py", line 214, in inner
    return func(self._wrapped, *args)
  File "/home/damon/Documents/Python/django-damon/django_test/userprofile/models.py", line 11, in <lambda>
    User.profile = property(lambda u:UserProfile.objects.get_or_create(user=u)[0])
  File "/home/damon/Documents/Python/django-damon/local/lib/python2.7/site-packages/Django-1.6.4-py2.7.egg/django/db/models/manager.py", line 154, in get_or_create
    return self.get_queryset().get_or_create(**kwargs)
  File "/home/damon/Documents/Python/django-damon/local/lib/python2.7/site-packages/Django-1.6.4-py2.7.egg/django/db/models/query.py", line 388, in get_or_create
    six.reraise(*exc_info)
  File "/home/damon/Documents/Python/django-damon/local/lib/python2.7/site-packages/Django-1.6.4-py2.7.egg/django/db/models/query.py", line 380, in get_or_create
    obj.save(force_insert=True, using=self.db)
  File "/home/damon/Documents/Python/django-damon/local/lib/python2.7/site-packages/Django-1.6.4-py2.7.egg/django/db/models/base.py", line 545, in save
    force_update=force_update, update_fields=update_fields)
  File "/home/damon/Documents/Python/django-damon/local/lib/python2.7/site-packages/Django-1.6.4-py2.7.egg/django/db/models/base.py", line 573, in save_base
    updated = self._save_table(raw, cls, force_insert, force_update, using, update_fields)
  File "/home/damon/Documents/Python/django-damon/local/lib/python2.7/site-packages/Django-1.6.4-py2.7.egg/django/db/models/base.py", line 654, in _save_table
    result = self._do_insert(cls._base_manager, using, fields, update_pk, raw)
  File "/home/damon/Documents/Python/django-damon/local/lib/python2.7/site-packages/Django-1.6.4-py2.7.egg/django/db/models/base.py", line 687, in _do_insert
    using=using, raw=raw)
  File "/home/damon/Documents/Python/django-damon/local/lib/python2.7/site-packages/Django-1.6.4-py2.7.egg/django/db/models/manager.py", line 232, in _insert
    return insert_query(self.model, objs, fields, **kwargs)
  File "/home/damon/Documents/Python/django-damon/local/lib/python2.7/site-packages/Django-1.6.4-py2.7.egg/django/db/models/query.py", line 1511, in insert_query
    return query.get_compiler(using=using).execute_sql(return_id)
  File "/home/damon/Documents/Python/django-damon/local/lib/python2.7/site-packages/Django-1.6.4-py2.7.egg/django/db/models/sql/compiler.py", line 903, in execute_sql
    cursor.execute(sql, params)
  File "/home/damon/Documents/Python/django-damon/local/lib/python2.7/site-packages/Django-1.6.4-py2.7.egg/django/db/backends/util.py", line 69, in execute
    return super(CursorDebugWrapper, self).execute(sql, params)
  File "/home/damon/Documents/Python/django-damon/local/lib/python2.7/site-packages/Django-1.6.4-py2.7.egg/django/db/backends/util.py", line 53, in execute
    return self.cursor.execute(sql, params)
  File "/home/damon/Documents/Python/django-damon/local/lib/python2.7/site-packages/Django-1.6.4-py2.7.egg/django/db/backends/mysql/base.py", line 129, in execute
    six.reraise(utils.IntegrityError, utils.IntegrityError(*tuple(e.args)), sys.exc_info()[2])
  File "/home/damon/Documents/Python/django-damon/local/lib/python2.7/site-packages/Django-1.6.4-py2.7.egg/django/db/backends/mysql/base.py", line 124, in execute
    return self.cursor.execute(query, args)
  File "/home/damon/Documents/Python/django-damon/local/lib/python2.7/site-packages/MySQL_python-1.2.5-py2.7-linux-x86_64.egg/MySQLdb/cursors.py", line 205, in execute
    self.errorhandler(self, exc, value)
  File "/home/damon/Documents/Python/django-damon/local/lib/python2.7/site-packages/MySQL_python-1.2.5-py2.7-linux-x86_64.egg/MySQLdb/connections.py", line 36, in defaulterrorhandler
    raise errorclass, errorvalue
IntegrityError: (1048, "Column 'likes_cheese' cannot be null")
2014-05-28 20:22:42,699 [ERROR] django.request: Internal Server Error: /accounts/profile/
Traceback (most recent call last):
  File "/home/damon/Documents/Python/django-damon/local/lib/python2.7/site-packages/Django-1.6.4-py2.7.egg/django/core/handlers/base.py", line 114, in get_response
    response = wrapped_callback(request, *callback_args, **callback_kwargs)
  File "/home/damon/Documents/Python/django-damon/local/lib/python2.7/site-packages/Django-1.6.4-py2.7.egg/django/contrib/auth/decorators.py", line 22, in _wrapped_view
    return view_func(request, *args, **kwargs)
  File "/home/damon/Documents/Python/django-damon/django_test/userprofile/views.py", line 17, in user_profile
    profile = user.profile
  File "/home/damon/Documents/Python/django-damon/local/lib/python2.7/site-packages/Django-1.6.4-py2.7.egg/django/utils/functional.py", line 214, in inner
    return func(self._wrapped, *args)
  File "/home/damon/Documents/Python/django-damon/django_test/userprofile/models.py", line 11, in <lambda>
    User.profile = property(lambda u:UserProfile.objects.get_or_create(user=u)[0])
  File "/home/damon/Documents/Python/django-damon/local/lib/python2.7/site-packages/Django-1.6.4-py2.7.egg/django/db/models/manager.py", line 154, in get_or_create
    return self.get_queryset().get_or_create(**kwargs)
  File "/home/damon/Documents/Python/django-damon/local/lib/python2.7/site-packages/Django-1.6.4-py2.7.egg/django/db/models/query.py", line 388, in get_or_create
    six.reraise(*exc_info)
  File "/home/damon/Documents/Python/django-damon/local/lib/python2.7/site-packages/Django-1.6.4-py2.7.egg/django/db/models/query.py", line 380, in get_or_create
    obj.save(force_insert=True, using=self.db)
  File "/home/damon/Documents/Python/django-damon/local/lib/python2.7/site-packages/Django-1.6.4-py2.7.egg/django/db/models/base.py", line 545, in save
    force_update=force_update, update_fields=update_fields)
  File "/home/damon/Documents/Python/django-damon/local/lib/python2.7/site-packages/Django-1.6.4-py2.7.egg/django/db/models/base.py", line 573, in save_base
    updated = self._save_table(raw, cls, force_insert, force_update, using, update_fields)
  File "/home/damon/Documents/Python/django-damon/local/lib/python2.7/site-packages/Django-1.6.4-py2.7.egg/django/db/models/base.py", line 654, in _save_table
    result = self._do_insert(cls._base_manager, using, fields, update_pk, raw)
  File "/home/damon/Documents/Python/django-damon/local/lib/python2.7/site-packages/Django-1.6.4-py2.7.egg/django/db/models/base.py", line 687, in _do_insert
    using=using, raw=raw)
  File "/home/damon/Documents/Python/django-damon/local/lib/python2.7/site-packages/Django-1.6.4-py2.7.egg/django/db/models/manager.py", line 232, in _insert
    return insert_query(self.model, objs, fields, **kwargs)
  File "/home/damon/Documents/Python/django-damon/local/lib/python2.7/site-packages/Django-1.6.4-py2.7.egg/django/db/models/query.py", line 1511, in insert_query
    return query.get_compiler(using=using).execute_sql(return_id)
  File "/home/damon/Documents/Python/django-damon/local/lib/python2.7/site-packages/Django-1.6.4-py2.7.egg/django/db/models/sql/compiler.py", line 903, in execute_sql
    cursor.execute(sql, params)
  File "/home/damon/Documents/Python/django-damon/local/lib/python2.7/site-packages/Django-1.6.4-py2.7.egg/django/db/backends/util.py", line 69, in execute
    return super(CursorDebugWrapper, self).execute(sql, params)
  File "/home/damon/Documents/Python/django-damon/local/lib/python2.7/site-packages/Django-1.6.4-py2.7.egg/django/db/backends/util.py", line 53, in execute
    return self.cursor.execute(sql, params)
  File "/home/damon/Documents/Python/django-damon/local/lib/python2.7/site-packages/Django-1.6.4-py2.7.egg/django/db/backends/mysql/base.py", line 129, in execute
    six.reraise(utils.IntegrityError, utils.IntegrityError(*tuple(e.args)), sys.exc_info()[2])
  File "/home/damon/Documents/Python/django-damon/local/lib/python2.7/site-packages/Django-1.6.4-py2.7.egg/django/db/backends/mysql/base.py", line 124, in execute
    return self.cursor.execute(query, args)
  File "/home/damon/Documents/Python/django-damon/local/lib/python2.7/site-packages/MySQL_python-1.2.5-py2.7-linux-x86_64.egg/MySQLdb/cursors.py", line 205, in execute
    self.errorhandler(self, exc, value)
  File "/home/damon/Documents/Python/django-damon/local/lib/python2.7/site-packages/MySQL_python-1.2.5-py2.7-linux-x86_64.egg/MySQLdb/connections.py", line 36, in defaulterrorhandler
    raise errorclass, errorvalue
IntegrityError: (1048, "Column 'likes_cheese' cannot be null")
2014-05-28 20:23:04,688 [ERROR] django.request: Internal Server Error: /accounts/profile/
Traceback (most recent call last):
  File "/home/damon/Documents/Python/django-damon/local/lib/python2.7/site-packages/Django-1.6.4-py2.7.egg/django/core/handlers/base.py", line 114, in get_response
    response = wrapped_callback(request, *callback_args, **callback_kwargs)
  File "/home/damon/Documents/Python/django-damon/local/lib/python2.7/site-packages/Django-1.6.4-py2.7.egg/django/contrib/auth/decorators.py", line 22, in _wrapped_view
    return view_func(request, *args, **kwargs)
  File "/home/damon/Documents/Python/django-damon/django_test/userprofile/views.py", line 17, in user_profile
    profile = user.profile
  File "/home/damon/Documents/Python/django-damon/local/lib/python2.7/site-packages/Django-1.6.4-py2.7.egg/django/utils/functional.py", line 214, in inner
    return func(self._wrapped, *args)
  File "/home/damon/Documents/Python/django-damon/django_test/userprofile/models.py", line 11, in <lambda>
    User.profile = property(lambda u:UserProfile.objects.get_or_create(user=u)[0])
  File "/home/damon/Documents/Python/django-damon/local/lib/python2.7/site-packages/Django-1.6.4-py2.7.egg/django/db/models/manager.py", line 154, in get_or_create
    return self.get_queryset().get_or_create(**kwargs)
  File "/home/damon/Documents/Python/django-damon/local/lib/python2.7/site-packages/Django-1.6.4-py2.7.egg/django/db/models/query.py", line 388, in get_or_create
    six.reraise(*exc_info)
  File "/home/damon/Documents/Python/django-damon/local/lib/python2.7/site-packages/Django-1.6.4-py2.7.egg/django/db/models/query.py", line 380, in get_or_create
    obj.save(force_insert=True, using=self.db)
  File "/home/damon/Documents/Python/django-damon/local/lib/python2.7/site-packages/Django-1.6.4-py2.7.egg/django/db/models/base.py", line 545, in save
    force_update=force_update, update_fields=update_fields)
  File "/home/damon/Documents/Python/django-damon/local/lib/python2.7/site-packages/Django-1.6.4-py2.7.egg/django/db/models/base.py", line 573, in save_base
    updated = self._save_table(raw, cls, force_insert, force_update, using, update_fields)
  File "/home/damon/Documents/Python/django-damon/local/lib/python2.7/site-packages/Django-1.6.4-py2.7.egg/django/db/models/base.py", line 654, in _save_table
    result = self._do_insert(cls._base_manager, using, fields, update_pk, raw)
  File "/home/damon/Documents/Python/django-damon/local/lib/python2.7/site-packages/Django-1.6.4-py2.7.egg/django/db/models/base.py", line 687, in _do_insert
    using=using, raw=raw)
  File "/home/damon/Documents/Python/django-damon/local/lib/python2.7/site-packages/Django-1.6.4-py2.7.egg/django/db/models/manager.py", line 232, in _insert
    return insert_query(self.model, objs, fields, **kwargs)
  File "/home/damon/Documents/Python/django-damon/local/lib/python2.7/site-packages/Django-1.6.4-py2.7.egg/django/db/models/query.py", line 1511, in insert_query
    return query.get_compiler(using=using).execute_sql(return_id)
  File "/home/damon/Documents/Python/django-damon/local/lib/python2.7/site-packages/Django-1.6.4-py2.7.egg/django/db/models/sql/compiler.py", line 903, in execute_sql
    cursor.execute(sql, params)
  File "/home/damon/Documents/Python/django-damon/local/lib/python2.7/site-packages/Django-1.6.4-py2.7.egg/django/db/backends/util.py", line 69, in execute
    return super(CursorDebugWrapper, self).execute(sql, params)
  File "/home/damon/Documents/Python/django-damon/local/lib/python2.7/site-packages/Django-1.6.4-py2.7.egg/django/db/backends/util.py", line 53, in execute
    return self.cursor.execute(sql, params)
  File "/home/damon/Documents/Python/django-damon/local/lib/python2.7/site-packages/Django-1.6.4-py2.7.egg/django/db/backends/mysql/base.py", line 129, in execute
    six.reraise(utils.IntegrityError, utils.IntegrityError(*tuple(e.args)), sys.exc_info()[2])
  File "/home/damon/Documents/Python/django-damon/local/lib/python2.7/site-packages/Django-1.6.4-py2.7.egg/django/db/backends/mysql/base.py", line 124, in execute
    return self.cursor.execute(query, args)
  File "/home/damon/Documents/Python/django-damon/local/lib/python2.7/site-packages/MySQL_python-1.2.5-py2.7-linux-x86_64.egg/MySQLdb/cursors.py", line 205, in execute
    self.errorhandler(self, exc, value)
  File "/home/damon/Documents/Python/django-damon/local/lib/python2.7/site-packages/MySQL_python-1.2.5-py2.7-linux-x86_64.egg/MySQLdb/connections.py", line 36, in defaulterrorhandler
    raise errorclass, errorvalue
IntegrityError: (1048, "Column 'likes_cheese' cannot be null")
2014-05-28 20:23:34,145 [ERROR] django.request: Internal Server Error: /accounts/profile/
Traceback (most recent call last):
  File "/home/damon/Documents/Python/django-damon/local/lib/python2.7/site-packages/Django-1.6.4-py2.7.egg/django/core/handlers/base.py", line 114, in get_response
    response = wrapped_callback(request, *callback_args, **callback_kwargs)
  File "/home/damon/Documents/Python/django-damon/local/lib/python2.7/site-packages/Django-1.6.4-py2.7.egg/django/contrib/auth/decorators.py", line 22, in _wrapped_view
    return view_func(request, *args, **kwargs)
  File "/home/damon/Documents/Python/django-damon/django_test/userprofile/views.py", line 17, in user_profile
    profile = user.profile
  File "/home/damon/Documents/Python/django-damon/local/lib/python2.7/site-packages/Django-1.6.4-py2.7.egg/django/utils/functional.py", line 214, in inner
    return func(self._wrapped, *args)
  File "/home/damon/Documents/Python/django-damon/django_test/userprofile/models.py", line 11, in <lambda>
    User.profile = property(lambda u:UserProfile.objects.get_or_create(user=u)[0])
  File "/home/damon/Documents/Python/django-damon/local/lib/python2.7/site-packages/Django-1.6.4-py2.7.egg/django/db/models/manager.py", line 154, in get_or_create
    return self.get_queryset().get_or_create(**kwargs)
  File "/home/damon/Documents/Python/django-damon/local/lib/python2.7/site-packages/Django-1.6.4-py2.7.egg/django/db/models/query.py", line 388, in get_or_create
    six.reraise(*exc_info)
  File "/home/damon/Documents/Python/django-damon/local/lib/python2.7/site-packages/Django-1.6.4-py2.7.egg/django/db/models/query.py", line 380, in get_or_create
    obj.save(force_insert=True, using=self.db)
  File "/home/damon/Documents/Python/django-damon/local/lib/python2.7/site-packages/Django-1.6.4-py2.7.egg/django/db/models/base.py", line 545, in save
    force_update=force_update, update_fields=update_fields)
  File "/home/damon/Documents/Python/django-damon/local/lib/python2.7/site-packages/Django-1.6.4-py2.7.egg/django/db/models/base.py", line 573, in save_base
    updated = self._save_table(raw, cls, force_insert, force_update, using, update_fields)
  File "/home/damon/Documents/Python/django-damon/local/lib/python2.7/site-packages/Django-1.6.4-py2.7.egg/django/db/models/base.py", line 654, in _save_table
    result = self._do_insert(cls._base_manager, using, fields, update_pk, raw)
  File "/home/damon/Documents/Python/django-damon/local/lib/python2.7/site-packages/Django-1.6.4-py2.7.egg/django/db/models/base.py", line 687, in _do_insert
    using=using, raw=raw)
  File "/home/damon/Documents/Python/django-damon/local/lib/python2.7/site-packages/Django-1.6.4-py2.7.egg/django/db/models/manager.py", line 232, in _insert
    return insert_query(self.model, objs, fields, **kwargs)
  File "/home/damon/Documents/Python/django-damon/local/lib/python2.7/site-packages/Django-1.6.4-py2.7.egg/django/db/models/query.py", line 1511, in insert_query
    return query.get_compiler(using=using).execute_sql(return_id)
  File "/home/damon/Documents/Python/django-damon/local/lib/python2.7/site-packages/Django-1.6.4-py2.7.egg/django/db/models/sql/compiler.py", line 903, in execute_sql
    cursor.execute(sql, params)
  File "/home/damon/Documents/Python/django-damon/local/lib/python2.7/site-packages/Django-1.6.4-py2.7.egg/django/db/backends/util.py", line 69, in execute
    return super(CursorDebugWrapper, self).execute(sql, params)
  File "/home/damon/Documents/Python/django-damon/local/lib/python2.7/site-packages/Django-1.6.4-py2.7.egg/django/db/backends/util.py", line 53, in execute
    return self.cursor.execute(sql, params)
  File "/home/damon/Documents/Python/django-damon/local/lib/python2.7/site-packages/Django-1.6.4-py2.7.egg/django/db/backends/mysql/base.py", line 129, in execute
    six.reraise(utils.IntegrityError, utils.IntegrityError(*tuple(e.args)), sys.exc_info()[2])
  File "/home/damon/Documents/Python/django-damon/local/lib/python2.7/site-packages/Django-1.6.4-py2.7.egg/django/db/backends/mysql/base.py", line 124, in execute
    return self.cursor.execute(query, args)
  File "/home/damon/Documents/Python/django-damon/local/lib/python2.7/site-packages/MySQL_python-1.2.5-py2.7-linux-x86_64.egg/MySQLdb/cursors.py", line 205, in execute
    self.errorhandler(self, exc, value)
  File "/home/damon/Documents/Python/django-damon/local/lib/python2.7/site-packages/MySQL_python-1.2.5-py2.7-linux-x86_64.egg/MySQLdb/connections.py", line 36, in defaulterrorhandler
    raise errorclass, errorvalue
IntegrityError: (1048, "Column 'likes_cheese' cannot be null")
2014-05-28 20:25:39,213 [ERROR] django.request: Internal Server Error: /accounts/profile/
Traceback (most recent call last):
  File "/home/damon/Documents/Python/django-damon/local/lib/python2.7/site-packages/Django-1.6.4-py2.7.egg/django/core/handlers/base.py", line 114, in get_response
    response = wrapped_callback(request, *callback_args, **callback_kwargs)
  File "/home/damon/Documents/Python/django-damon/local/lib/python2.7/site-packages/Django-1.6.4-py2.7.egg/django/contrib/auth/decorators.py", line 22, in _wrapped_view
    return view_func(request, *args, **kwargs)
  File "/home/damon/Documents/Python/django-damon/django_test/userprofile/views.py", line 18, in user_profile
    profile = user.profile
  File "/home/damon/Documents/Python/django-damon/local/lib/python2.7/site-packages/Django-1.6.4-py2.7.egg/django/utils/functional.py", line 214, in inner
    return func(self._wrapped, *args)
  File "/home/damon/Documents/Python/django-damon/django_test/userprofile/models.py", line 11, in <lambda>
    User.profile = property(lambda u:UserProfile.objects.get_or_create(user=u)[0])
  File "/home/damon/Documents/Python/django-damon/local/lib/python2.7/site-packages/Django-1.6.4-py2.7.egg/django/db/models/manager.py", line 154, in get_or_create
    return self.get_queryset().get_or_create(**kwargs)
  File "/home/damon/Documents/Python/django-damon/local/lib/python2.7/site-packages/Django-1.6.4-py2.7.egg/django/db/models/query.py", line 388, in get_or_create
    six.reraise(*exc_info)
  File "/home/damon/Documents/Python/django-damon/local/lib/python2.7/site-packages/Django-1.6.4-py2.7.egg/django/db/models/query.py", line 380, in get_or_create
    obj.save(force_insert=True, using=self.db)
  File "/home/damon/Documents/Python/django-damon/local/lib/python2.7/site-packages/Django-1.6.4-py2.7.egg/django/db/models/base.py", line 545, in save
    force_update=force_update, update_fields=update_fields)
  File "/home/damon/Documents/Python/django-damon/local/lib/python2.7/site-packages/Django-1.6.4-py2.7.egg/django/db/models/base.py", line 573, in save_base
    updated = self._save_table(raw, cls, force_insert, force_update, using, update_fields)
  File "/home/damon/Documents/Python/django-damon/local/lib/python2.7/site-packages/Django-1.6.4-py2.7.egg/django/db/models/base.py", line 654, in _save_table
    result = self._do_insert(cls._base_manager, using, fields, update_pk, raw)
  File "/home/damon/Documents/Python/django-damon/local/lib/python2.7/site-packages/Django-1.6.4-py2.7.egg/django/db/models/base.py", line 687, in _do_insert
    using=using, raw=raw)
  File "/home/damon/Documents/Python/django-damon/local/lib/python2.7/site-packages/Django-1.6.4-py2.7.egg/django/db/models/manager.py", line 232, in _insert
    return insert_query(self.model, objs, fields, **kwargs)
  File "/home/damon/Documents/Python/django-damon/local/lib/python2.7/site-packages/Django-1.6.4-py2.7.egg/django/db/models/query.py", line 1511, in insert_query
    return query.get_compiler(using=using).execute_sql(return_id)
  File "/home/damon/Documents/Python/django-damon/local/lib/python2.7/site-packages/Django-1.6.4-py2.7.egg/django/db/models/sql/compiler.py", line 903, in execute_sql
    cursor.execute(sql, params)
  File "/home/damon/Documents/Python/django-damon/local/lib/python2.7/site-packages/Django-1.6.4-py2.7.egg/django/db/backends/util.py", line 69, in execute
    return super(CursorDebugWrapper, self).execute(sql, params)
  File "/home/damon/Documents/Python/django-damon/local/lib/python2.7/site-packages/Django-1.6.4-py2.7.egg/django/db/backends/util.py", line 53, in execute
    return self.cursor.execute(sql, params)
  File "/home/damon/Documents/Python/django-damon/local/lib/python2.7/site-packages/Django-1.6.4-py2.7.egg/django/db/backends/mysql/base.py", line 129, in execute
    six.reraise(utils.IntegrityError, utils.IntegrityError(*tuple(e.args)), sys.exc_info()[2])
  File "/home/damon/Documents/Python/django-damon/local/lib/python2.7/site-packages/Django-1.6.4-py2.7.egg/django/db/backends/mysql/base.py", line 124, in execute
    return self.cursor.execute(query, args)
  File "/home/damon/Documents/Python/django-damon/local/lib/python2.7/site-packages/MySQL_python-1.2.5-py2.7-linux-x86_64.egg/MySQLdb/cursors.py", line 205, in execute
    self.errorhandler(self, exc, value)
  File "/home/damon/Documents/Python/django-damon/local/lib/python2.7/site-packages/MySQL_python-1.2.5-py2.7-linux-x86_64.egg/MySQLdb/connections.py", line 36, in defaulterrorhandler
    raise errorclass, errorvalue
IntegrityError: (1048, "Column 'likes_cheese' cannot be null")
2014-05-28 20:26:29,212 [ERROR] django.request: Internal Server Error: /accounts/profile/
Traceback (most recent call last):
  File "/home/damon/Documents/Python/django-damon/local/lib/python2.7/site-packages/Django-1.6.4-py2.7.egg/django/core/handlers/base.py", line 114, in get_response
    response = wrapped_callback(request, *callback_args, **callback_kwargs)
  File "/home/damon/Documents/Python/django-damon/local/lib/python2.7/site-packages/Django-1.6.4-py2.7.egg/django/contrib/auth/decorators.py", line 22, in _wrapped_view
    return view_func(request, *args, **kwargs)
  File "/home/damon/Documents/Python/django-damon/django_test/userprofile/views.py", line 17, in user_profile
    print request.user, request.user.profile
  File "/home/damon/Documents/Python/django-damon/local/lib/python2.7/site-packages/Django-1.6.4-py2.7.egg/django/utils/functional.py", line 214, in inner
    return func(self._wrapped, *args)
  File "/home/damon/Documents/Python/django-damon/django_test/userprofile/models.py", line 11, in <lambda>
    User.profile = property(lambda u:UserProfile.objects.get_or_create(user=u)[0])
  File "/home/damon/Documents/Python/django-damon/local/lib/python2.7/site-packages/Django-1.6.4-py2.7.egg/django/db/models/manager.py", line 154, in get_or_create
    return self.get_queryset().get_or_create(**kwargs)
  File "/home/damon/Documents/Python/django-damon/local/lib/python2.7/site-packages/Django-1.6.4-py2.7.egg/django/db/models/query.py", line 388, in get_or_create
    six.reraise(*exc_info)
  File "/home/damon/Documents/Python/django-damon/local/lib/python2.7/site-packages/Django-1.6.4-py2.7.egg/django/db/models/query.py", line 380, in get_or_create
    obj.save(force_insert=True, using=self.db)
  File "/home/damon/Documents/Python/django-damon/local/lib/python2.7/site-packages/Django-1.6.4-py2.7.egg/django/db/models/base.py", line 545, in save
    force_update=force_update, update_fields=update_fields)
  File "/home/damon/Documents/Python/django-damon/local/lib/python2.7/site-packages/Django-1.6.4-py2.7.egg/django/db/models/base.py", line 573, in save_base
    updated = self._save_table(raw, cls, force_insert, force_update, using, update_fields)
  File "/home/damon/Documents/Python/django-damon/local/lib/python2.7/site-packages/Django-1.6.4-py2.7.egg/django/db/models/base.py", line 654, in _save_table
    result = self._do_insert(cls._base_manager, using, fields, update_pk, raw)
  File "/home/damon/Documents/Python/django-damon/local/lib/python2.7/site-packages/Django-1.6.4-py2.7.egg/django/db/models/base.py", line 687, in _do_insert
    using=using, raw=raw)
  File "/home/damon/Documents/Python/django-damon/local/lib/python2.7/site-packages/Django-1.6.4-py2.7.egg/django/db/models/manager.py", line 232, in _insert
    return insert_query(self.model, objs, fields, **kwargs)
  File "/home/damon/Documents/Python/django-damon/local/lib/python2.7/site-packages/Django-1.6.4-py2.7.egg/django/db/models/query.py", line 1511, in insert_query
    return query.get_compiler(using=using).execute_sql(return_id)
  File "/home/damon/Documents/Python/django-damon/local/lib/python2.7/site-packages/Django-1.6.4-py2.7.egg/django/db/models/sql/compiler.py", line 903, in execute_sql
    cursor.execute(sql, params)
  File "/home/damon/Documents/Python/django-damon/local/lib/python2.7/site-packages/Django-1.6.4-py2.7.egg/django/db/backends/util.py", line 69, in execute
    return super(CursorDebugWrapper, self).execute(sql, params)
  File "/home/damon/Documents/Python/django-damon/local/lib/python2.7/site-packages/Django-1.6.4-py2.7.egg/django/db/backends/util.py", line 53, in execute
    return self.cursor.execute(sql, params)
  File "/home/damon/Documents/Python/django-damon/local/lib/python2.7/site-packages/Django-1.6.4-py2.7.egg/django/db/backends/mysql/base.py", line 129, in execute
    six.reraise(utils.IntegrityError, utils.IntegrityError(*tuple(e.args)), sys.exc_info()[2])
  File "/home/damon/Documents/Python/django-damon/local/lib/python2.7/site-packages/Django-1.6.4-py2.7.egg/django/db/backends/mysql/base.py", line 124, in execute
    return self.cursor.execute(query, args)
  File "/home/damon/Documents/Python/django-damon/local/lib/python2.7/site-packages/MySQL_python-1.2.5-py2.7-linux-x86_64.egg/MySQLdb/cursors.py", line 205, in execute
    self.errorhandler(self, exc, value)
  File "/home/damon/Documents/Python/django-damon/local/lib/python2.7/site-packages/MySQL_python-1.2.5-py2.7-linux-x86_64.egg/MySQLdb/connections.py", line 36, in defaulterrorhandler
    raise errorclass, errorvalue
IntegrityError: (1048, "Column 'likes_cheese' cannot be null")
2014-05-28 20:26:54,426 [ERROR] django.request: Internal Server Error: /accounts/profile/
Traceback (most recent call last):
  File "/home/damon/Documents/Python/django-damon/local/lib/python2.7/site-packages/Django-1.6.4-py2.7.egg/django/core/handlers/base.py", line 114, in get_response
    response = wrapped_callback(request, *callback_args, **callback_kwargs)
  File "/home/damon/Documents/Python/django-damon/local/lib/python2.7/site-packages/Django-1.6.4-py2.7.egg/django/contrib/auth/decorators.py", line 22, in _wrapped_view
    return view_func(request, *args, **kwargs)
  File "/home/damon/Documents/Python/django-damon/django_test/userprofile/views.py", line 17, in user_profile
    print request.user, request.user.profile
  File "/home/damon/Documents/Python/django-damon/local/lib/python2.7/site-packages/Django-1.6.4-py2.7.egg/django/utils/functional.py", line 214, in inner
    return func(self._wrapped, *args)
  File "/home/damon/Documents/Python/django-damon/django_test/userprofile/models.py", line 11, in <lambda>
    User.profile = property(lambda u:UserProfile.objects.get_or_create(user=u)[0])
  File "/home/damon/Documents/Python/django-damon/local/lib/python2.7/site-packages/Django-1.6.4-py2.7.egg/django/db/models/manager.py", line 154, in get_or_create
    return self.get_queryset().get_or_create(**kwargs)
  File "/home/damon/Documents/Python/django-damon/local/lib/python2.7/site-packages/Django-1.6.4-py2.7.egg/django/db/models/query.py", line 388, in get_or_create
    six.reraise(*exc_info)
  File "/home/damon/Documents/Python/django-damon/local/lib/python2.7/site-packages/Django-1.6.4-py2.7.egg/django/db/models/query.py", line 380, in get_or_create
    obj.save(force_insert=True, using=self.db)
  File "/home/damon/Documents/Python/django-damon/local/lib/python2.7/site-packages/Django-1.6.4-py2.7.egg/django/db/models/base.py", line 545, in save
    force_update=force_update, update_fields=update_fields)
  File "/home/damon/Documents/Python/django-damon/local/lib/python2.7/site-packages/Django-1.6.4-py2.7.egg/django/db/models/base.py", line 573, in save_base
    updated = self._save_table(raw, cls, force_insert, force_update, using, update_fields)
  File "/home/damon/Documents/Python/django-damon/local/lib/python2.7/site-packages/Django-1.6.4-py2.7.egg/django/db/models/base.py", line 654, in _save_table
    result = self._do_insert(cls._base_manager, using, fields, update_pk, raw)
  File "/home/damon/Documents/Python/django-damon/local/lib/python2.7/site-packages/Django-1.6.4-py2.7.egg/django/db/models/base.py", line 687, in _do_insert
    using=using, raw=raw)
  File "/home/damon/Documents/Python/django-damon/local/lib/python2.7/site-packages/Django-1.6.4-py2.7.egg/django/db/models/manager.py", line 232, in _insert
    return insert_query(self.model, objs, fields, **kwargs)
  File "/home/damon/Documents/Python/django-damon/local/lib/python2.7/site-packages/Django-1.6.4-py2.7.egg/django/db/models/query.py", line 1511, in insert_query
    return query.get_compiler(using=using).execute_sql(return_id)
  File "/home/damon/Documents/Python/django-damon/local/lib/python2.7/site-packages/Django-1.6.4-py2.7.egg/django/db/models/sql/compiler.py", line 903, in execute_sql
    cursor.execute(sql, params)
  File "/home/damon/Documents/Python/django-damon/local/lib/python2.7/site-packages/Django-1.6.4-py2.7.egg/django/db/backends/util.py", line 69, in execute
    return super(CursorDebugWrapper, self).execute(sql, params)
  File "/home/damon/Documents/Python/django-damon/local/lib/python2.7/site-packages/Django-1.6.4-py2.7.egg/django/db/backends/util.py", line 53, in execute
    return self.cursor.execute(sql, params)
  File "/home/damon/Documents/Python/django-damon/local/lib/python2.7/site-packages/Django-1.6.4-py2.7.egg/django/db/backends/mysql/base.py", line 129, in execute
    six.reraise(utils.IntegrityError, utils.IntegrityError(*tuple(e.args)), sys.exc_info()[2])
  File "/home/damon/Documents/Python/django-damon/local/lib/python2.7/site-packages/Django-1.6.4-py2.7.egg/django/db/backends/mysql/base.py", line 124, in execute
    return self.cursor.execute(query, args)
  File "/home/damon/Documents/Python/django-damon/local/lib/python2.7/site-packages/MySQL_python-1.2.5-py2.7-linux-x86_64.egg/MySQLdb/cursors.py", line 205, in execute
    self.errorhandler(self, exc, value)
  File "/home/damon/Documents/Python/django-damon/local/lib/python2.7/site-packages/MySQL_python-1.2.5-py2.7-linux-x86_64.egg/MySQLdb/connections.py", line 36, in defaulterrorhandler
    raise errorclass, errorvalue
IntegrityError: (1048, "Column 'likes_cheese' cannot be null")
2014-05-28 20:27:27,084 [ERROR] django.request: Internal Server Error: /accounts/profile/
Traceback (most recent call last):
  File "/home/damon/Documents/Python/django-damon/local/lib/python2.7/site-packages/Django-1.6.4-py2.7.egg/django/core/handlers/base.py", line 114, in get_response
    response = wrapped_callback(request, *callback_args, **callback_kwargs)
  File "/home/damon/Documents/Python/django-damon/local/lib/python2.7/site-packages/Django-1.6.4-py2.7.egg/django/contrib/auth/decorators.py", line 22, in _wrapped_view
    return view_func(request, *args, **kwargs)
  File "/home/damon/Documents/Python/django-damon/django_test/userprofile/views.py", line 18, in user_profile
    print request.user, request.user.profile
  File "/home/damon/Documents/Python/django-damon/local/lib/python2.7/site-packages/Django-1.6.4-py2.7.egg/django/utils/functional.py", line 214, in inner
    return func(self._wrapped, *args)
  File "/home/damon/Documents/Python/django-damon/django_test/userprofile/models.py", line 11, in <lambda>
    User.profile = property(lambda u:UserProfile.objects.get_or_create(user=u)[0])
  File "/home/damon/Documents/Python/django-damon/local/lib/python2.7/site-packages/Django-1.6.4-py2.7.egg/django/db/models/manager.py", line 154, in get_or_create
    return self.get_queryset().get_or_create(**kwargs)
  File "/home/damon/Documents/Python/django-damon/local/lib/python2.7/site-packages/Django-1.6.4-py2.7.egg/django/db/models/query.py", line 388, in get_or_create
    six.reraise(*exc_info)
  File "/home/damon/Documents/Python/django-damon/local/lib/python2.7/site-packages/Django-1.6.4-py2.7.egg/django/db/models/query.py", line 380, in get_or_create
    obj.save(force_insert=True, using=self.db)
  File "/home/damon/Documents/Python/django-damon/local/lib/python2.7/site-packages/Django-1.6.4-py2.7.egg/django/db/models/base.py", line 545, in save
    force_update=force_update, update_fields=update_fields)
  File "/home/damon/Documents/Python/django-damon/local/lib/python2.7/site-packages/Django-1.6.4-py2.7.egg/django/db/models/base.py", line 573, in save_base
    updated = self._save_table(raw, cls, force_insert, force_update, using, update_fields)
  File "/home/damon/Documents/Python/django-damon/local/lib/python2.7/site-packages/Django-1.6.4-py2.7.egg/django/db/models/base.py", line 654, in _save_table
    result = self._do_insert(cls._base_manager, using, fields, update_pk, raw)
  File "/home/damon/Documents/Python/django-damon/local/lib/python2.7/site-packages/Django-1.6.4-py2.7.egg/django/db/models/base.py", line 687, in _do_insert
    using=using, raw=raw)
  File "/home/damon/Documents/Python/django-damon/local/lib/python2.7/site-packages/Django-1.6.4-py2.7.egg/django/db/models/manager.py", line 232, in _insert
    return insert_query(self.model, objs, fields, **kwargs)
  File "/home/damon/Documents/Python/django-damon/local/lib/python2.7/site-packages/Django-1.6.4-py2.7.egg/django/db/models/query.py", line 1511, in insert_query
    return query.get_compiler(using=using).execute_sql(return_id)
  File "/home/damon/Documents/Python/django-damon/local/lib/python2.7/site-packages/Django-1.6.4-py2.7.egg/django/db/models/sql/compiler.py", line 903, in execute_sql
    cursor.execute(sql, params)
  File "/home/damon/Documents/Python/django-damon/local/lib/python2.7/site-packages/Django-1.6.4-py2.7.egg/django/db/backends/util.py", line 69, in execute
    return super(CursorDebugWrapper, self).execute(sql, params)
  File "/home/damon/Documents/Python/django-damon/local/lib/python2.7/site-packages/Django-1.6.4-py2.7.egg/django/db/backends/util.py", line 53, in execute
    return self.cursor.execute(sql, params)
  File "/home/damon/Documents/Python/django-damon/local/lib/python2.7/site-packages/Django-1.6.4-py2.7.egg/django/db/backends/mysql/base.py", line 129, in execute
    six.reraise(utils.IntegrityError, utils.IntegrityError(*tuple(e.args)), sys.exc_info()[2])
  File "/home/damon/Documents/Python/django-damon/local/lib/python2.7/site-packages/Django-1.6.4-py2.7.egg/django/db/backends/mysql/base.py", line 124, in execute
    return self.cursor.execute(query, args)
  File "/home/damon/Documents/Python/django-damon/local/lib/python2.7/site-packages/MySQL_python-1.2.5-py2.7-linux-x86_64.egg/MySQLdb/cursors.py", line 205, in execute
    self.errorhandler(self, exc, value)
  File "/home/damon/Documents/Python/django-damon/local/lib/python2.7/site-packages/MySQL_python-1.2.5-py2.7-linux-x86_64.egg/MySQLdb/connections.py", line 36, in defaulterrorhandler
    raise errorclass, errorvalue
IntegrityError: (1048, "Column 'likes_cheese' cannot be null")
2014-05-28 20:27:45,350 [ERROR] django.request: Internal Server Error: /accounts/profile/
Traceback (most recent call last):
  File "/home/damon/Documents/Python/django-damon/local/lib/python2.7/site-packages/Django-1.6.4-py2.7.egg/django/core/handlers/base.py", line 114, in get_response
    response = wrapped_callback(request, *callback_args, **callback_kwargs)
  File "/home/damon/Documents/Python/django-damon/local/lib/python2.7/site-packages/Django-1.6.4-py2.7.egg/django/contrib/auth/decorators.py", line 22, in _wrapped_view
    return view_func(request, *args, **kwargs)
  File "/home/damon/Documents/Python/django-damon/django_test/userprofile/views.py", line 19, in user_profile
    print request.user, request.user.profile
  File "/home/damon/Documents/Python/django-damon/local/lib/python2.7/site-packages/Django-1.6.4-py2.7.egg/django/utils/functional.py", line 214, in inner
    return func(self._wrapped, *args)
  File "/home/damon/Documents/Python/django-damon/django_test/userprofile/models.py", line 11, in <lambda>
    User.profile = property(lambda u:UserProfile.objects.get_or_create(user=u)[0])
  File "/home/damon/Documents/Python/django-damon/local/lib/python2.7/site-packages/Django-1.6.4-py2.7.egg/django/db/models/manager.py", line 154, in get_or_create
    return self.get_queryset().get_or_create(**kwargs)
  File "/home/damon/Documents/Python/django-damon/local/lib/python2.7/site-packages/Django-1.6.4-py2.7.egg/django/db/models/query.py", line 388, in get_or_create
    six.reraise(*exc_info)
  File "/home/damon/Documents/Python/django-damon/local/lib/python2.7/site-packages/Django-1.6.4-py2.7.egg/django/db/models/query.py", line 380, in get_or_create
    obj.save(force_insert=True, using=self.db)
  File "/home/damon/Documents/Python/django-damon/local/lib/python2.7/site-packages/Django-1.6.4-py2.7.egg/django/db/models/base.py", line 545, in save
    force_update=force_update, update_fields=update_fields)
  File "/home/damon/Documents/Python/django-damon/local/lib/python2.7/site-packages/Django-1.6.4-py2.7.egg/django/db/models/base.py", line 573, in save_base
    updated = self._save_table(raw, cls, force_insert, force_update, using, update_fields)
  File "/home/damon/Documents/Python/django-damon/local/lib/python2.7/site-packages/Django-1.6.4-py2.7.egg/django/db/models/base.py", line 654, in _save_table
    result = self._do_insert(cls._base_manager, using, fields, update_pk, raw)
  File "/home/damon/Documents/Python/django-damon/local/lib/python2.7/site-packages/Django-1.6.4-py2.7.egg/django/db/models/base.py", line 687, in _do_insert
    using=using, raw=raw)
  File "/home/damon/Documents/Python/django-damon/local/lib/python2.7/site-packages/Django-1.6.4-py2.7.egg/django/db/models/manager.py", line 232, in _insert
    return insert_query(self.model, objs, fields, **kwargs)
  File "/home/damon/Documents/Python/django-damon/local/lib/python2.7/site-packages/Django-1.6.4-py2.7.egg/django/db/models/query.py", line 1511, in insert_query
    return query.get_compiler(using=using).execute_sql(return_id)
  File "/home/damon/Documents/Python/django-damon/local/lib/python2.7/site-packages/Django-1.6.4-py2.7.egg/django/db/models/sql/compiler.py", line 903, in execute_sql
    cursor.execute(sql, params)
  File "/home/damon/Documents/Python/django-damon/local/lib/python2.7/site-packages/Django-1.6.4-py2.7.egg/django/db/backends/util.py", line 69, in execute
    return super(CursorDebugWrapper, self).execute(sql, params)
  File "/home/damon/Documents/Python/django-damon/local/lib/python2.7/site-packages/Django-1.6.4-py2.7.egg/django/db/backends/util.py", line 53, in execute
    return self.cursor.execute(sql, params)
  File "/home/damon/Documents/Python/django-damon/local/lib/python2.7/site-packages/Django-1.6.4-py2.7.egg/django/db/backends/mysql/base.py", line 129, in execute
    six.reraise(utils.IntegrityError, utils.IntegrityError(*tuple(e.args)), sys.exc_info()[2])
  File "/home/damon/Documents/Python/django-damon/local/lib/python2.7/site-packages/Django-1.6.4-py2.7.egg/django/db/backends/mysql/base.py", line 124, in execute
    return self.cursor.execute(query, args)
  File "/home/damon/Documents/Python/django-damon/local/lib/python2.7/site-packages/MySQL_python-1.2.5-py2.7-linux-x86_64.egg/MySQLdb/cursors.py", line 205, in execute
    self.errorhandler(self, exc, value)
  File "/home/damon/Documents/Python/django-damon/local/lib/python2.7/site-packages/MySQL_python-1.2.5-py2.7-linux-x86_64.egg/MySQLdb/connections.py", line 36, in defaulterrorhandler
    raise errorclass, errorvalue
IntegrityError: (1048, "Column 'likes_cheese' cannot be null")
2014-05-28 20:28:39,726 [ERROR] django.request: Internal Server Error: /accounts/profile/
Traceback (most recent call last):
  File "/home/damon/Documents/Python/django-damon/local/lib/python2.7/site-packages/Django-1.6.4-py2.7.egg/django/core/handlers/base.py", line 114, in get_response
    response = wrapped_callback(request, *callback_args, **callback_kwargs)
  File "/home/damon/Documents/Python/django-damon/local/lib/python2.7/site-packages/Django-1.6.4-py2.7.egg/django/contrib/auth/decorators.py", line 22, in _wrapped_view
    return view_func(request, *args, **kwargs)
  File "/home/damon/Documents/Python/django-damon/django_test/userprofile/views.py", line 21, in user_profile
    profile = user.profile
  File "/home/damon/Documents/Python/django-damon/local/lib/python2.7/site-packages/Django-1.6.4-py2.7.egg/django/utils/functional.py", line 214, in inner
    return func(self._wrapped, *args)
  File "/home/damon/Documents/Python/django-damon/django_test/userprofile/models.py", line 11, in <lambda>
    User.profile = property(lambda u:UserProfile.objects.get_or_create(user=u)[0])
  File "/home/damon/Documents/Python/django-damon/local/lib/python2.7/site-packages/Django-1.6.4-py2.7.egg/django/db/models/manager.py", line 154, in get_or_create
    return self.get_queryset().get_or_create(**kwargs)
  File "/home/damon/Documents/Python/django-damon/local/lib/python2.7/site-packages/Django-1.6.4-py2.7.egg/django/db/models/query.py", line 388, in get_or_create
    six.reraise(*exc_info)
  File "/home/damon/Documents/Python/django-damon/local/lib/python2.7/site-packages/Django-1.6.4-py2.7.egg/django/db/models/query.py", line 380, in get_or_create
    obj.save(force_insert=True, using=self.db)
  File "/home/damon/Documents/Python/django-damon/local/lib/python2.7/site-packages/Django-1.6.4-py2.7.egg/django/db/models/base.py", line 545, in save
    force_update=force_update, update_fields=update_fields)
  File "/home/damon/Documents/Python/django-damon/local/lib/python2.7/site-packages/Django-1.6.4-py2.7.egg/django/db/models/base.py", line 573, in save_base
    updated = self._save_table(raw, cls, force_insert, force_update, using, update_fields)
  File "/home/damon/Documents/Python/django-damon/local/lib/python2.7/site-packages/Django-1.6.4-py2.7.egg/django/db/models/base.py", line 654, in _save_table
    result = self._do_insert(cls._base_manager, using, fields, update_pk, raw)
  File "/home/damon/Documents/Python/django-damon/local/lib/python2.7/site-packages/Django-1.6.4-py2.7.egg/django/db/models/base.py", line 687, in _do_insert
    using=using, raw=raw)
  File "/home/damon/Documents/Python/django-damon/local/lib/python2.7/site-packages/Django-1.6.4-py2.7.egg/django/db/models/manager.py", line 232, in _insert
    return insert_query(self.model, objs, fields, **kwargs)
  File "/home/damon/Documents/Python/django-damon/local/lib/python2.7/site-packages/Django-1.6.4-py2.7.egg/django/db/models/query.py", line 1511, in insert_query
    return query.get_compiler(using=using).execute_sql(return_id)
  File "/home/damon/Documents/Python/django-damon/local/lib/python2.7/site-packages/Django-1.6.4-py2.7.egg/django/db/models/sql/compiler.py", line 903, in execute_sql
    cursor.execute(sql, params)
  File "/home/damon/Documents/Python/django-damon/local/lib/python2.7/site-packages/Django-1.6.4-py2.7.egg/django/db/backends/util.py", line 69, in execute
    return super(CursorDebugWrapper, self).execute(sql, params)
  File "/home/damon/Documents/Python/django-damon/local/lib/python2.7/site-packages/Django-1.6.4-py2.7.egg/django/db/backends/util.py", line 53, in execute
    return self.cursor.execute(sql, params)
  File "/home/damon/Documents/Python/django-damon/local/lib/python2.7/site-packages/Django-1.6.4-py2.7.egg/django/db/backends/mysql/base.py", line 129, in execute
    six.reraise(utils.IntegrityError, utils.IntegrityError(*tuple(e.args)), sys.exc_info()[2])
  File "/home/damon/Documents/Python/django-damon/local/lib/python2.7/site-packages/Django-1.6.4-py2.7.egg/django/db/backends/mysql/base.py", line 124, in execute
    return self.cursor.execute(query, args)
  File "/home/damon/Documents/Python/django-damon/local/lib/python2.7/site-packages/MySQL_python-1.2.5-py2.7-linux-x86_64.egg/MySQLdb/cursors.py", line 205, in execute
    self.errorhandler(self, exc, value)
  File "/home/damon/Documents/Python/django-damon/local/lib/python2.7/site-packages/MySQL_python-1.2.5-py2.7-linux-x86_64.egg/MySQLdb/connections.py", line 36, in defaulterrorhandler
    raise errorclass, errorvalue
IntegrityError: (1048, "Column 'likes_cheese' cannot be null")
2014-05-28 20:29:03,659 [WARNING] django.request: Not Found: /accounts
2014-05-28 20:29:25,170 [ERROR] django.request: Internal Server Error: /accounts/profile/
Traceback (most recent call last):
  File "/home/damon/Documents/Python/django-damon/local/lib/python2.7/site-packages/Django-1.6.4-py2.7.egg/django/core/handlers/base.py", line 114, in get_response
    response = wrapped_callback(request, *callback_args, **callback_kwargs)
  File "/home/damon/Documents/Python/django-damon/local/lib/python2.7/site-packages/Django-1.6.4-py2.7.egg/django/contrib/auth/decorators.py", line 22, in _wrapped_view
    return view_func(request, *args, **kwargs)
  File "/home/damon/Documents/Python/django-damon/django_test/userprofile/views.py", line 21, in user_profile
    profile = user.profile
  File "/home/damon/Documents/Python/django-damon/local/lib/python2.7/site-packages/Django-1.6.4-py2.7.egg/django/utils/functional.py", line 214, in inner
    return func(self._wrapped, *args)
  File "/home/damon/Documents/Python/django-damon/django_test/userprofile/models.py", line 11, in <lambda>
    User.profile = property(lambda u:UserProfile.objects.get_or_create(user=u)[0])
  File "/home/damon/Documents/Python/django-damon/local/lib/python2.7/site-packages/Django-1.6.4-py2.7.egg/django/db/models/manager.py", line 154, in get_or_create
    return self.get_queryset().get_or_create(**kwargs)
  File "/home/damon/Documents/Python/django-damon/local/lib/python2.7/site-packages/Django-1.6.4-py2.7.egg/django/db/models/query.py", line 388, in get_or_create
    six.reraise(*exc_info)
  File "/home/damon/Documents/Python/django-damon/local/lib/python2.7/site-packages/Django-1.6.4-py2.7.egg/django/db/models/query.py", line 380, in get_or_create
    obj.save(force_insert=True, using=self.db)
  File "/home/damon/Documents/Python/django-damon/local/lib/python2.7/site-packages/Django-1.6.4-py2.7.egg/django/db/models/base.py", line 545, in save
    force_update=force_update, update_fields=update_fields)
  File "/home/damon/Documents/Python/django-damon/local/lib/python2.7/site-packages/Django-1.6.4-py2.7.egg/django/db/models/base.py", line 573, in save_base
    updated = self._save_table(raw, cls, force_insert, force_update, using, update_fields)
  File "/home/damon/Documents/Python/django-damon/local/lib/python2.7/site-packages/Django-1.6.4-py2.7.egg/django/db/models/base.py", line 654, in _save_table
    result = self._do_insert(cls._base_manager, using, fields, update_pk, raw)
  File "/home/damon/Documents/Python/django-damon/local/lib/python2.7/site-packages/Django-1.6.4-py2.7.egg/django/db/models/base.py", line 687, in _do_insert
    using=using, raw=raw)
  File "/home/damon/Documents/Python/django-damon/local/lib/python2.7/site-packages/Django-1.6.4-py2.7.egg/django/db/models/manager.py", line 232, in _insert
    return insert_query(self.model, objs, fields, **kwargs)
  File "/home/damon/Documents/Python/django-damon/local/lib/python2.7/site-packages/Django-1.6.4-py2.7.egg/django/db/models/query.py", line 1511, in insert_query
    return query.get_compiler(using=using).execute_sql(return_id)
  File "/home/damon/Documents/Python/django-damon/local/lib/python2.7/site-packages/Django-1.6.4-py2.7.egg/django/db/models/sql/compiler.py", line 903, in execute_sql
    cursor.execute(sql, params)
  File "/home/damon/Documents/Python/django-damon/local/lib/python2.7/site-packages/Django-1.6.4-py2.7.egg/django/db/backends/util.py", line 69, in execute
    return super(CursorDebugWrapper, self).execute(sql, params)
  File "/home/damon/Documents/Python/django-damon/local/lib/python2.7/site-packages/Django-1.6.4-py2.7.egg/django/db/backends/util.py", line 53, in execute
    return self.cursor.execute(sql, params)
  File "/home/damon/Documents/Python/django-damon/local/lib/python2.7/site-packages/Django-1.6.4-py2.7.egg/django/db/backends/mysql/base.py", line 129, in execute
    six.reraise(utils.IntegrityError, utils.IntegrityError(*tuple(e.args)), sys.exc_info()[2])
  File "/home/damon/Documents/Python/django-damon/local/lib/python2.7/site-packages/Django-1.6.4-py2.7.egg/django/db/backends/mysql/base.py", line 124, in execute
    return self.cursor.execute(query, args)
  File "/home/damon/Documents/Python/django-damon/local/lib/python2.7/site-packages/MySQL_python-1.2.5-py2.7-linux-x86_64.egg/MySQLdb/cursors.py", line 205, in execute
    self.errorhandler(self, exc, value)
  File "/home/damon/Documents/Python/django-damon/local/lib/python2.7/site-packages/MySQL_python-1.2.5-py2.7-linux-x86_64.egg/MySQLdb/connections.py", line 36, in defaulterrorhandler
    raise errorclass, errorvalue
IntegrityError: (1048, "Column 'likes_cheese' cannot be null")
2014-05-28 20:29:53,893 [ERROR] django.request: Internal Server Error: /accounts/profile/
Traceback (most recent call last):
  File "/home/damon/Documents/Python/django-damon/local/lib/python2.7/site-packages/Django-1.6.4-py2.7.egg/django/core/handlers/base.py", line 114, in get_response
    response = wrapped_callback(request, *callback_args, **callback_kwargs)
  File "/home/damon/Documents/Python/django-damon/local/lib/python2.7/site-packages/Django-1.6.4-py2.7.egg/django/contrib/auth/decorators.py", line 22, in _wrapped_view
    return view_func(request, *args, **kwargs)
  File "/home/damon/Documents/Python/django-damon/django_test/userprofile/views.py", line 21, in user_profile
    profile = user.profile
  File "/home/damon/Documents/Python/django-damon/local/lib/python2.7/site-packages/Django-1.6.4-py2.7.egg/django/utils/functional.py", line 214, in inner
    return func(self._wrapped, *args)
  File "/home/damon/Documents/Python/django-damon/django_test/userprofile/models.py", line 11, in <lambda>
    User.profile = property(lambda u:UserProfile.objects.get_or_create(user=u)[0])
  File "/home/damon/Documents/Python/django-damon/local/lib/python2.7/site-packages/Django-1.6.4-py2.7.egg/django/db/models/manager.py", line 154, in get_or_create
    return self.get_queryset().get_or_create(**kwargs)
  File "/home/damon/Documents/Python/django-damon/local/lib/python2.7/site-packages/Django-1.6.4-py2.7.egg/django/db/models/query.py", line 388, in get_or_create
    six.reraise(*exc_info)
  File "/home/damon/Documents/Python/django-damon/local/lib/python2.7/site-packages/Django-1.6.4-py2.7.egg/django/db/models/query.py", line 380, in get_or_create
    obj.save(force_insert=True, using=self.db)
  File "/home/damon/Documents/Python/django-damon/local/lib/python2.7/site-packages/Django-1.6.4-py2.7.egg/django/db/models/base.py", line 545, in save
    force_update=force_update, update_fields=update_fields)
  File "/home/damon/Documents/Python/django-damon/local/lib/python2.7/site-packages/Django-1.6.4-py2.7.egg/django/db/models/base.py", line 573, in save_base
    updated = self._save_table(raw, cls, force_insert, force_update, using, update_fields)
  File "/home/damon/Documents/Python/django-damon/local/lib/python2.7/site-packages/Django-1.6.4-py2.7.egg/django/db/models/base.py", line 654, in _save_table
    result = self._do_insert(cls._base_manager, using, fields, update_pk, raw)
  File "/home/damon/Documents/Python/django-damon/local/lib/python2.7/site-packages/Django-1.6.4-py2.7.egg/django/db/models/base.py", line 687, in _do_insert
    using=using, raw=raw)
  File "/home/damon/Documents/Python/django-damon/local/lib/python2.7/site-packages/Django-1.6.4-py2.7.egg/django/db/models/manager.py", line 232, in _insert
    return insert_query(self.model, objs, fields, **kwargs)
  File "/home/damon/Documents/Python/django-damon/local/lib/python2.7/site-packages/Django-1.6.4-py2.7.egg/django/db/models/query.py", line 1511, in insert_query
    return query.get_compiler(using=using).execute_sql(return_id)
  File "/home/damon/Documents/Python/django-damon/local/lib/python2.7/site-packages/Django-1.6.4-py2.7.egg/django/db/models/sql/compiler.py", line 903, in execute_sql
    cursor.execute(sql, params)
  File "/home/damon/Documents/Python/django-damon/local/lib/python2.7/site-packages/Django-1.6.4-py2.7.egg/django/db/backends/util.py", line 69, in execute
    return super(CursorDebugWrapper, self).execute(sql, params)
  File "/home/damon/Documents/Python/django-damon/local/lib/python2.7/site-packages/Django-1.6.4-py2.7.egg/django/db/backends/util.py", line 53, in execute
    return self.cursor.execute(sql, params)
  File "/home/damon/Documents/Python/django-damon/local/lib/python2.7/site-packages/Django-1.6.4-py2.7.egg/django/db/backends/mysql/base.py", line 129, in execute
    six.reraise(utils.IntegrityError, utils.IntegrityError(*tuple(e.args)), sys.exc_info()[2])
  File "/home/damon/Documents/Python/django-damon/local/lib/python2.7/site-packages/Django-1.6.4-py2.7.egg/django/db/backends/mysql/base.py", line 124, in execute
    return self.cursor.execute(query, args)
  File "/home/damon/Documents/Python/django-damon/local/lib/python2.7/site-packages/MySQL_python-1.2.5-py2.7-linux-x86_64.egg/MySQLdb/cursors.py", line 205, in execute
    self.errorhandler(self, exc, value)
  File "/home/damon/Documents/Python/django-damon/local/lib/python2.7/site-packages/MySQL_python-1.2.5-py2.7-linux-x86_64.egg/MySQLdb/connections.py", line 36, in defaulterrorhandler
    raise errorclass, errorvalue
IntegrityError: (1048, "Column 'likes_cheese' cannot be null")
2014-05-28 20:30:36,936 [ERROR] django.request: Internal Server Error: /accounts/profile/
Traceback (most recent call last):
  File "/home/damon/Documents/Python/django-damon/local/lib/python2.7/site-packages/Django-1.6.4-py2.7.egg/django/core/handlers/base.py", line 114, in get_response
    response = wrapped_callback(request, *callback_args, **callback_kwargs)
  File "/home/damon/Documents/Python/django-damon/local/lib/python2.7/site-packages/Django-1.6.4-py2.7.egg/django/contrib/auth/decorators.py", line 22, in _wrapped_view
    return view_func(request, *args, **kwargs)
  File "/home/damon/Documents/Python/django-damon/django_test/userprofile/views.py", line 21, in user_profile
    print "+++", user.profile
  File "/home/damon/Documents/Python/django-damon/local/lib/python2.7/site-packages/Django-1.6.4-py2.7.egg/django/utils/functional.py", line 214, in inner
    return func(self._wrapped, *args)
  File "/home/damon/Documents/Python/django-damon/django_test/userprofile/models.py", line 11, in <lambda>
    User.profile = property(lambda u:UserProfile.objects.get_or_create(user=u)[0])
  File "/home/damon/Documents/Python/django-damon/local/lib/python2.7/site-packages/Django-1.6.4-py2.7.egg/django/db/models/manager.py", line 154, in get_or_create
    return self.get_queryset().get_or_create(**kwargs)
  File "/home/damon/Documents/Python/django-damon/local/lib/python2.7/site-packages/Django-1.6.4-py2.7.egg/django/db/models/query.py", line 388, in get_or_create
    six.reraise(*exc_info)
  File "/home/damon/Documents/Python/django-damon/local/lib/python2.7/site-packages/Django-1.6.4-py2.7.egg/django/db/models/query.py", line 380, in get_or_create
    obj.save(force_insert=True, using=self.db)
  File "/home/damon/Documents/Python/django-damon/local/lib/python2.7/site-packages/Django-1.6.4-py2.7.egg/django/db/models/base.py", line 545, in save
    force_update=force_update, update_fields=update_fields)
  File "/home/damon/Documents/Python/django-damon/local/lib/python2.7/site-packages/Django-1.6.4-py2.7.egg/django/db/models/base.py", line 573, in save_base
    updated = self._save_table(raw, cls, force_insert, force_update, using, update_fields)
  File "/home/damon/Documents/Python/django-damon/local/lib/python2.7/site-packages/Django-1.6.4-py2.7.egg/django/db/models/base.py", line 654, in _save_table
    result = self._do_insert(cls._base_manager, using, fields, update_pk, raw)
  File "/home/damon/Documents/Python/django-damon/local/lib/python2.7/site-packages/Django-1.6.4-py2.7.egg/django/db/models/base.py", line 687, in _do_insert
    using=using, raw=raw)
  File "/home/damon/Documents/Python/django-damon/local/lib/python2.7/site-packages/Django-1.6.4-py2.7.egg/django/db/models/manager.py", line 232, in _insert
    return insert_query(self.model, objs, fields, **kwargs)
  File "/home/damon/Documents/Python/django-damon/local/lib/python2.7/site-packages/Django-1.6.4-py2.7.egg/django/db/models/query.py", line 1511, in insert_query
    return query.get_compiler(using=using).execute_sql(return_id)
  File "/home/damon/Documents/Python/django-damon/local/lib/python2.7/site-packages/Django-1.6.4-py2.7.egg/django/db/models/sql/compiler.py", line 903, in execute_sql
    cursor.execute(sql, params)
  File "/home/damon/Documents/Python/django-damon/local/lib/python2.7/site-packages/Django-1.6.4-py2.7.egg/django/db/backends/util.py", line 69, in execute
    return super(CursorDebugWrapper, self).execute(sql, params)
  File "/home/damon/Documents/Python/django-damon/local/lib/python2.7/site-packages/Django-1.6.4-py2.7.egg/django/db/backends/util.py", line 53, in execute
    return self.cursor.execute(sql, params)
  File "/home/damon/Documents/Python/django-damon/local/lib/python2.7/site-packages/Django-1.6.4-py2.7.egg/django/db/backends/mysql/base.py", line 129, in execute
    six.reraise(utils.IntegrityError, utils.IntegrityError(*tuple(e.args)), sys.exc_info()[2])
  File "/home/damon/Documents/Python/django-damon/local/lib/python2.7/site-packages/Django-1.6.4-py2.7.egg/django/db/backends/mysql/base.py", line 124, in execute
    return self.cursor.execute(query, args)
  File "/home/damon/Documents/Python/django-damon/local/lib/python2.7/site-packages/MySQL_python-1.2.5-py2.7-linux-x86_64.egg/MySQLdb/cursors.py", line 205, in execute
    self.errorhandler(self, exc, value)
  File "/home/damon/Documents/Python/django-damon/local/lib/python2.7/site-packages/MySQL_python-1.2.5-py2.7-linux-x86_64.egg/MySQLdb/connections.py", line 36, in defaulterrorhandler
    raise errorclass, errorvalue
IntegrityError: (1048, "Column 'likes_cheese' cannot be null")
2014-05-28 20:35:00,409 [ERROR] django.request: Internal Server Error: /accounts/profile/
Traceback (most recent call last):
  File "/home/damon/Documents/Python/django-damon/local/lib/python2.7/site-packages/Django-1.6.4-py2.7.egg/django/core/handlers/base.py", line 114, in get_response
    response = wrapped_callback(request, *callback_args, **callback_kwargs)
  File "/home/damon/Documents/Python/django-damon/local/lib/python2.7/site-packages/Django-1.6.4-py2.7.egg/django/contrib/auth/decorators.py", line 22, in _wrapped_view
    return view_func(request, *args, **kwargs)
  File "/home/damon/Documents/Python/django-damon/django_test/userprofile/views.py", line 18, in user_profile
    profile = user.profile
  File "/home/damon/Documents/Python/django-damon/local/lib/python2.7/site-packages/Django-1.6.4-py2.7.egg/django/utils/functional.py", line 214, in inner
    return func(self._wrapped, *args)
  File "/home/damon/Documents/Python/django-damon/django_test/userprofile/models.py", line 11, in <lambda>
    User.profile = property(lambda u:UserProfile.objects.get_or_create(user=u)[0])
  File "/home/damon/Documents/Python/django-damon/local/lib/python2.7/site-packages/Django-1.6.4-py2.7.egg/django/db/models/manager.py", line 154, in get_or_create
    return self.get_queryset().get_or_create(**kwargs)
  File "/home/damon/Documents/Python/django-damon/local/lib/python2.7/site-packages/Django-1.6.4-py2.7.egg/django/db/models/query.py", line 388, in get_or_create
    six.reraise(*exc_info)
  File "/home/damon/Documents/Python/django-damon/local/lib/python2.7/site-packages/Django-1.6.4-py2.7.egg/django/db/models/query.py", line 380, in get_or_create
    obj.save(force_insert=True, using=self.db)
  File "/home/damon/Documents/Python/django-damon/local/lib/python2.7/site-packages/Django-1.6.4-py2.7.egg/django/db/models/base.py", line 545, in save
    force_update=force_update, update_fields=update_fields)
  File "/home/damon/Documents/Python/django-damon/local/lib/python2.7/site-packages/Django-1.6.4-py2.7.egg/django/db/models/base.py", line 573, in save_base
    updated = self._save_table(raw, cls, force_insert, force_update, using, update_fields)
  File "/home/damon/Documents/Python/django-damon/local/lib/python2.7/site-packages/Django-1.6.4-py2.7.egg/django/db/models/base.py", line 654, in _save_table
    result = self._do_insert(cls._base_manager, using, fields, update_pk, raw)
  File "/home/damon/Documents/Python/django-damon/local/lib/python2.7/site-packages/Django-1.6.4-py2.7.egg/django/db/models/base.py", line 687, in _do_insert
    using=using, raw=raw)
  File "/home/damon/Documents/Python/django-damon/local/lib/python2.7/site-packages/Django-1.6.4-py2.7.egg/django/db/models/manager.py", line 232, in _insert
    return insert_query(self.model, objs, fields, **kwargs)
  File "/home/damon/Documents/Python/django-damon/local/lib/python2.7/site-packages/Django-1.6.4-py2.7.egg/django/db/models/query.py", line 1511, in insert_query
    return query.get_compiler(using=using).execute_sql(return_id)
  File "/home/damon/Documents/Python/django-damon/local/lib/python2.7/site-packages/Django-1.6.4-py2.7.egg/django/db/models/sql/compiler.py", line 903, in execute_sql
    cursor.execute(sql, params)
  File "/home/damon/Documents/Python/django-damon/local/lib/python2.7/site-packages/Django-1.6.4-py2.7.egg/django/db/backends/util.py", line 69, in execute
    return super(CursorDebugWrapper, self).execute(sql, params)
  File "/home/damon/Documents/Python/django-damon/local/lib/python2.7/site-packages/Django-1.6.4-py2.7.egg/django/db/backends/util.py", line 53, in execute
    return self.cursor.execute(sql, params)
  File "/home/damon/Documents/Python/django-damon/local/lib/python2.7/site-packages/Django-1.6.4-py2.7.egg/django/db/backends/mysql/base.py", line 129, in execute
    six.reraise(utils.IntegrityError, utils.IntegrityError(*tuple(e.args)), sys.exc_info()[2])
  File "/home/damon/Documents/Python/django-damon/local/lib/python2.7/site-packages/Django-1.6.4-py2.7.egg/django/db/backends/mysql/base.py", line 124, in execute
    return self.cursor.execute(query, args)
  File "/home/damon/Documents/Python/django-damon/local/lib/python2.7/site-packages/MySQL_python-1.2.5-py2.7-linux-x86_64.egg/MySQLdb/cursors.py", line 205, in execute
    self.errorhandler(self, exc, value)
  File "/home/damon/Documents/Python/django-damon/local/lib/python2.7/site-packages/MySQL_python-1.2.5-py2.7-linux-x86_64.egg/MySQLdb/connections.py", line 36, in defaulterrorhandler
    raise errorclass, errorvalue
IntegrityError: (1048, "Column 'likes_cheese' cannot be null")
2014-05-28 20:38:59,291 [ERROR] django.request: Internal Server Error: /accounts/profile/
Traceback (most recent call last):
  File "/home/damon/Documents/Python/django-damon/local/lib/python2.7/site-packages/Django-1.6.4-py2.7.egg/django/core/handlers/base.py", line 114, in get_response
    response = wrapped_callback(request, *callback_args, **callback_kwargs)
  File "/home/damon/Documents/Python/django-damon/local/lib/python2.7/site-packages/Django-1.6.4-py2.7.egg/django/contrib/auth/decorators.py", line 22, in _wrapped_view
    return view_func(request, *args, **kwargs)
  File "/home/damon/Documents/Python/django-damon/django_test/userprofile/views.py", line 26, in user_profile
    return render_to_response('profile.html', args)
NameError: global name 'render_to_response' is not defined
2014-05-28 20:40:15,699 [ERROR] django.request: Internal Server Error: /accounts/profile/
Traceback (most recent call last):
  File "/home/damon/Documents/Python/django-damon/local/lib/python2.7/site-packages/Django-1.6.4-py2.7.egg/django/core/handlers/base.py", line 114, in get_response
    response = wrapped_callback(request, *callback_args, **callback_kwargs)
  File "/home/damon/Documents/Python/django-damon/local/lib/python2.7/site-packages/Django-1.6.4-py2.7.egg/django/contrib/auth/decorators.py", line 22, in _wrapped_view
    return view_func(request, *args, **kwargs)
  File "/home/damon/Documents/Python/django-damon/django_test/userprofile/views.py", line 11, in user_profile
    form = UserProfileForm(request.POST, instance==request.user.profile)
NameError: global name 'instance' is not defined
2014-05-28 20:45:40,029 [WARNING] django.request: Not Found: /favicon.ico
